Workbook
Name ENMO: 'Data Validation'!$C$14:$C$36
Name ESWM_FOCAL: 'Data Validation'!$E$14:$E$19
Name ESWM_STAFF: 'Data Validation'!$D$14

Sheet ENMO TARGET
A1: No. | B1: PROVINCE | C1: ENMO | D1: 10 Year Plan | E1: MRF | F1: Equipment | G1: ODS | H1: SLF | I1: Transfer Station | J1: RCA | K1: Trash Trap | L1: Preliminary Disinpection Facility
A2: 1 | B2: AURORA | C2: Zaila Mae R. Leander | D2: 4 | E2: 12 | F2: 3 | G2: 1 | H2: 1 | J2: 2 | L2: 1
A3: 2 | B3: AURORA | C3: Nikko Jay M. Valenzuela | D3: 2 | E3: 4 | F3: 2 | H3: 2 | L3: 1
A4: 3 | B4: AURORA | C4: Queenyvel R. Laguisma | D4: 3 | E4: 3 | F4: 3 | J4: 3 | L4: 1
A5: 4 | B5: BATAAN | C5: Dennis G. Tolentino | D5: 6 | E5: 10 | F5: 6 | G5: 2 | H5: 3 | L5: 1
A6: 5 | B6: BATAAN | C6: John-lester C. Signio | D6: 4 | E6: 4 | F6: 4 | G6: 3 | L6: 1
A7: 6 | B7: BATAAN | C7: Laurence Radasa | D7: 3 | E7: 12 | F7: 3 | G7: 2 | I7: 1 | J7: 2
A8: 7 | B8: BULACAN | C8: Jasmine Marie J. Nicolas | D8: 5 | E8: 7 | F8: 6 | I8: 3 | K8: 21
A9: 8 | B9: BULACAN | C9: Ronaldo P. Roque Jr. | D9: 5 | E9: 5 | F9: 5 | G9: 2 | I9: 2 | K9: 8
A10: 9 | B10: BULACAN | C10: Vacant
A11: 10 | B11: BULACAN | C11: James Wilson T. Peña | D11: 6 | E11: 8 | F11: 6 | G11: 2 | K11: 7 | L11: 2
A12: 11 | B12: NUEVA ECIJA | C12: Hosannah R. Sabio | D12: 6 | E12: 6 | F12: 7 | G12: 4 | I12: 6 | L12: 2
A13: 12 | B13: NUEVA ECIJA | C13: Gem C. Vicencio | D13: 6 | E13: 6 | F13: 6 | G13: 5 | I13: 6
A14: 13 | B14: NUEVA ECIJA | C14: Jan Emerson C. Gonzales | D14: 7 | E14: 9 | F14: 7 | H14: 2 | I14: 4 | J14: 1
A15: 14 | B15: NUEVA ECIJA | C15: Aser A. Inocencio, Jr. | D15: 7 | E15: 10 | F15: 8 | G15: 1 | H15: 1 | I15: 3 | J15: 3 | L15: 1
A16: 15 | B16: NUEVA ECIJA | C16: Christine Ann V. Ramos | D16: 6 | E16: 7 | F16: 7 | G16: 4 | I16: 6 | K16: 11 | L16: 1
A17: 16 | B17: PAMPANGA | C17: Roger T. Encarnacion II | D17: 6 | E17: 7 | F17: 6 | G17: 6 | K17: 8
A18: 17 | B18: PAMPANGA | C18: Elyza A. Evilla | D18: 5 | E18: 6 | F18: 5 | H18: 3 | I18: 2 | K18: 31 | L18: 4
A19: 18 | B19: PAMPANGA | C19: Glaiza S.Gaza | D19: 5 | E19: 6 | F19: 5 | G19: 4 | I19: 2 | K19: 14
A20: 19 | B20: PAMPANGA | C20: Ivy M. Castro | D20: 5 | E20: 4 | F20: 5 | G20: 2 | I20: 2 | K20: 13
A21: 20 | B21: TARLAC | C21: Joshua A. Capones | D21: 7 | E21: 6 | F21: 6 | G21: 1 | I21: 1 | L21: 2
A22: 21 | B22: TARLAC | C22: Jasper Kieht B. Pili | D22: 6 | E22: 5 | F22: 6 | G22: 1
A23: 22 | B23: TARLAC | C23: Gretzhen M. Apolonio | D23: 6 | E23: 7 | F23: 7 | H23: 1
A24: 23 | B24: ZAMBALES | C24: Larizze A. Santos | D24: 5 | E24: 5 | F24: 5 | G24: 2 | H24: 1 | I24: 2 | J24: 2 | L24: 2
A25: 24 | B25: ZAMBALES | C25: Vacant
A26: 25 | B26: ZAMBALES | C26: Ryan Ace R. Angel | D26: 3 | E26: 12 | F26: 3 | G26: 1 | H26: 2

Sheet Summary of Target
A3: 10 Year Plan | B3: Target Month
A4: Province | B4: 3.March | C4: Grand Total
A5: Aurora | B5: 1 | C5: 1
A6: Bataan | B6: 1 | C6: 1
A7: Bulacan | B7: 2 | C7: 2
A8: Nueva Ecija | B8: 3 | C8: 3
A9: Pampanga | B9: 3 | C9: 3
A10: Tarlac | B10: 2 | C10: 2
A11: Zambales | B11: 1 | C11: 1
A12: Grand Total | B12: 13 | C12: 13
A17: FUNDED MRF | B17: Target Month
A18: Province | B18: 3.March | C18: Grand Total
A19: Bataan | B19: 2 | C19: 2
A20: Bulacan | B20: 3 | C20: 3
A21: Nueva Ecija | B21: 3 | C21: 3
A22: Pampanga | B22: 1 | C22: 1
A23: Tarlac | B23: 1 | C23: 1
A24: Zambales | B24: 1 | C24: 1
A25: Grand Total | B25: 11 | C25: 11
A30: Sanitary landfill | B30: Target Month
A31: Province | B31: 3.March | C31: Grand Total
A32: Aurora | B32: 1 | C32: 1
A33: Pampanga | B33: 1 | C33: 1
A34: Grand Total | B34: 2 | C34: 2
A41: Open Dumpsite | B41: Target Month
A42: Province | B42: 4.April | C42: (blank) | D42: Grand Total
A43: Bulacan | B43: 1 | D43: 1
A44: Zambales
A45: Grand Total | B45: 1 | D45: 1
A48: Funded Equipment | B48: Target Month
A49: Province | B49: 3.March | C49: Grand Total
A50: Bataan | B50: 2 | C50: 2
A51: Bulacan | B51: 3 | C51: 3
A52: Nueva Ecija | B52: 4 | C52: 4
A53: Pampanga | B53: 2 | C53: 2
A54: Tarlac | B54: 2 | C54: 2
A55: Zambales | B55: 1 | C55: 1
A56: Grand Total | B56: 14 | C56: 14
A67: LGU Intiated MRF | B67: Target Month
A68: Province | B68: 3.March | C68: Grand Total
...

Sheet Data Validation
A1: Type of Plan | C1: SLF | H1: MRF | K1: EQUIPEMENT | M1: ODS | Q1: PDS | T1: TRASH TRAP | W1: TRANSFER STATION | AD1: RCA
A2: Municipal / City Plan | B2: YES | H2: OPERATIONAL | K2: OPERATIONAL | M2: FULLY REHABILITATED | N2: COMPLIANT | Q2: OPERATIONAL | T2: OPERATIONAL | W2: OPERATIONAL | X2: FACILITY | Y2: LGU | AD2: OPERATIONAL | AE2: FACILITY
A3: Provincial Plan | B3: NO | H3: NON-OPERATIONAL | K3: NON-OPERATIONAL | M3: PARTIAL REHABILITATED | N3: NOT COMPLIANT | Q3: NON-OPERATIONAL | T3: NON-OPERATIONAL | W3: NON-OPERATIONAL | X3: BIN | Y3: PRIVATE OWNERSHIP | AD3: NON-OPERATIONAL | AE3: BIN
H4: UNDER CONSTRUCTION | K4: PLANNING TO TRANSFER | M4: NOT YET REHABILITATED | Q4: PLANNING TO TRANSFER | W4: UNDER CONSTRUCTION | AD4: UNDER CONSTRUCTION
B5: YES | H5: OPERATING AS OPEN DUMPSITE | K5: PLANNING TO RETURN | M5: OPERATING AS OPEN DUMPSITE | Q5: OTHER | W5: OPERATING AS OPEN DUMPSITE | AD5: OPERATING AS OPEN DUMPSITE
B6: NO
A7: Type of MRF | B7: N/A
A8: EMB FUNDED MRF
A9: EMB FUNDED BRGY MRF
A10: LGU FUNDED MRF
A13: 1.January | C13: LIST OF ENMO | D13: ESWM STAFF | E13: ESWM FOCAL
A14: 2.February | C14: Queenyvel R. Laguisma | D14: Maria Cecilia S. Pascual | E14: Diozelle L. Cabalar
A15: 3.March | C15: Zaila Mae R. Leander | E15: Christle D. David
A16: 4.April | C16: Nikko Jay M. Valenzuela | E16: Zosimo P. Suyat
A17: 5.May | C17: Laurence Radasa | E17: Sherwin John Y. Loquellano
A18: 6.June | C18: John-Lester C. Signio | E18: Jun D. Guillermo
A19: 7.July | C19: Dennis G. Tolentino | E19: Jan Emerson C. Gonzales
A20: 8.August | C20: Ronaldo P. Roque Jr
A21: 9.September | C21: Jasmin Marie N. Siapco
A22: 10.October | C22: James Wilson T. Peña
A23: 11.November | C23: Aser A. Inocencio Jr.
A24: 12.December | C24: Christine Ann V. Ramos
C25: Gem C. Vicencio
C26: Christian Jem L. Buluran
C27: Hosannah R. Sabio
C28: Elyza A. Evilla
C29: Glaiza S. Gaza
C30: Roger T. Encarnacion II
C31: Joshua A. Capones
C32: Gretzhen A. Collado
C33: Jasper Kieht B. Pili
C34: Larizze Anne A. Santos
C35: Ryan Ace R. Angel
C36: Sebastian Josh V. Manalang

Sheet SUMMARY
A1: Monitoring of Approved 10 Year Plan | B1: Based on WFP 2026 Target is 126
B2: Approved Plan is 126 LGU and 4 Province
A5: EMB Funded MRF | B5: Removal of Duplicate EMB Funded MRF of Brgy Binuangan Obando Bulacan 2017
B6: Concerned regarding the status of the Funded MRF that has remarks of unsed/demolished/transform to another facility and closed due to land ownership
A8: SLF | B8: MCWMC Removal to Monitoring Target
A10: Brgy Technical Assistance | B10: Based on WFP 2026 Target is 1,677
B11: The number barangay that are not monitored is 1,248 only
A14: Transfer Station | B14: Removal of the TS that was monitored as component of Central MRF
A16: RCA | B16: Removal of the RCA that was monitored as component of Central MRF

Sheet 10-YEAR SWM PLAN
A1: Province | B1: Municipality | C1: Concatenate | D1: Manila Bay Area (MBA) | E1: Congressional District | F1: Long. | G1: Lat. | H1: Location | I1: Type of SWM Plan | J1: Resolution No. | K1: Period Covered | L1: Year Approved | M1: End Period | N1: For Renewal | O1: ENMO Assigned | P1: ESWM Staff | Q1: Focal Person | R1: Target Month | S1: IIS NUMBER | T1: Date of Monitoring | U1: Date Report Prepared (Submitted to IIS by ENMO) | V1: Date Report Reviewed (by ESWM Staff) | W1: Date Report Reviewed (by Focal Person) | X1: Date Report Approved | Y1: Total No. of Days (Report prepared) | Z1: Total No. of Days (Report Reviewed by ESWM Staff) | AA1: Total No. of Days (Report Reviewed by Focal) | AB1: Total No. of Days (Report Approved by C, ESWM) | AC1: Tracking of Reports (To be filled out by Planning Section) | AD1: PCG | AE1: Total Waste Generation | AF1: Waste Diversion Rate (%) | AG1: LGU Final Disposal | AH1: Remarks and Recommendation (Compliant/ Non-Compliant) | AI1: a. source reduction activities at source are present | AJ1: b. Collection segregated collection | AK1: c. Storage and setout (Segregation at source) | AL1: d. Processing MRF | AM1: e. Transfer Station | AN1: f. Disposal Facilities | AO1: Advise Letter/Notice Date Issued | AP1: Compliance to Advise/ Letter Issued | AQ1: Remarks | AR1: Biodegradable Wastes (kg/day) | AS1: Bio (%) | AT1: Recyclable Wastes (kg/day) | AU1: Recyclable (%) | AV1: Residual with potential (kg/day) | AW1: Residual with Potential (%) | AX1: Residual Wastes for Disposal (kg/day) | AY1: Residual (%) | AZ1: Special Wastes (kg/day) | BA1: Special (%) | BB1: Waste Diversion Rate (%) | BC1: Disposal Rate (%) | BD1: Signed Document
A2: Bataan | B2: Dinalupihan | C2: =CONCATENATE(A2,","," ",B2) -> Bataan, Dinalupihan | D2: MBA | E2: 3rd | F2: 14.866933 | G2: 120.4611 | H2: =CONCATENATE(F2,",",G2) -> 14.866933,120.461103 | I2: Municipal / City Plan | J2: NSWMC Resoution No. 149-A, Series of 2025 | K2: 2025-2034 | L2: 2025 | M2: 2034 | N2: Approved | O2: John-lester Signio | Q2: Christle D. David | R2: 1.January | S2: R3-2026-000641 | T2: 46034 | U2: 46034 | W2: 46035 | X2: 46039 | Y2: =IFERROR( IF( OR(ISBLANK(T2), ISBLANK(U2)), "", MAX( 1, IF( NETWORKDAYS(T2, U2, Holiday_Dates) <= 0, 1, NETWORKDAYS(T2, U2, Holiday_Dates) - IF(T2 = U2, 0, 1) ) ) ), "" ) -> 1 | Z2: =IF( OR(ISBLANK(U2), ISBLANK(V2)), "", MAX( 1, IF( NETWORKDAYS(U2, V2, Holiday_Dates) <= 0, 1, NETWORKDAYS(U2, V2, Holiday_Dates) - IF(U2 = V2, 0, 1) ) ) ) | AA2: =IFERROR( IF( OR(ISBLANK(W2), AND(ISBLANK(U2), ISBLANK(V2))), "", MAX( 1, IF( NETWORKDAYS(IF(NOT(ISBLANK(V2)), V2, U2), W2, Holiday_Dates) <= 0, 1, NETWORKDAYS(IF(NOT(ISBLANK(V2)), V2, U2), W2, Holiday_Dates) - IF(IF(NOT(ISBLANK(V2)), V2, U2) = W2, 0, 1) ) ) ), "" ) -> 1 | AB2: =IFERROR( IF( OR(ISBLANK(W2), ISBLANK(X2)), "", MAX( 1, IF( NETWORKDAYS(W2, X2, Holiday_Dates) <= 0, 1, NETWORKDAYS(W2, X2, Holiday_Dates) - IF(W2 = X2, 0, 1) ) ) ), "" ) -> 3 | AC2: Marshalle Julluice V. Catua | AD2: 0.668 | AE2: 82453.24 | AF2: 93.32 | AG2: Floridablanca Enviro Corporation | AH2: Compliant | AI2: YES | AJ2: YES | AK2: YES | AL2: YES | AN2: YES | AR2: 45374.02 | AS2: 0.5503 | AT2: 29402.83 | AU2: 0.3566 | AV2: 2168.52 | AW2: 0.0263 | AX2: 3042.52 | AY2: 0.0369 | AZ2: 2465.35 | BA2: 0.0299 | BB2: =SUM(AS2,AU2,AW2) -> 0.9332 | BC2: =SUM(AS2,AU2,AW2) -> 0.9332 | BD2: https://embco-my.sharepoint.com/:w:/g/personal/eswmr3_emb_gov_ph/IQD7bEqKn0GsTI_TzqPuNDVXAc0qXRdO4blA_DzluhQNwt8?e=94dpdL
A3: Bulacan | B3: Marilao | C3: =CONCATENATE(A3,","," ",B3) -> Bulacan, Marilao | D3: MBA | E3: 4th | F3: 14.774122 | G3: 120.95918 | H3: =CONCATENATE(F3,",",G3) -> 14.774122,120.959182 | I3: Municipal / City Plan | J3: No.1427 Series of 2020 | K3: 2019 - 2029 | L3: 2020 | M3: 2029 | N3: For Renewal | O3: James Wilson T. Pena | Q3: Diozelle L. Cabalar | R3: 1.January | S3: R3-2026-001826 | T3: 46043 | U3: 46043 | W3: 46043 | X3: 46044 | Y3: =IFERROR( IF( OR(ISBLANK(T3), ISBLANK(U3)), "", MAX( 1, IF( NETWORKDAYS(T3, U3, Holiday_Dates) <= 0, 1, NETWORKDAYS(T3, U3, Holiday_Dates) - IF(T3 = U3, 0, 1) ) ) ), "" ) -> 1 | Z3: =IF( OR(ISBLANK(U3), ISBLANK(V3)), "", MAX( 1, IF( NETWORKDAYS(U3, V3, Holiday_Dates) <= 0, 1, NETWORKDAYS(U3, V3, Holiday_Dates) - IF(U3 = V3, 0, 1) ) ) ) | AA3: =IFERROR( IF( OR(ISBLANK(W3), AND(ISBLANK(U3), ISBLANK(V3))), "", MAX( 1, IF( NETWORKDAYS(IF(NOT(ISBLANK(V3)), V3, U3), W3, Holiday_Dates) <= 0, 1, NETWORKDAYS(IF(NOT(ISBLANK(V3)), V3, U3), W3, Holiday_Dates) - IF(IF(NOT(ISBLANK(V3)), V3, U3) = W3, 0, 1) ) ) ), "" ) -> 1 | AB3: =IFERROR( IF( OR(ISBLANK(W3), ISBLANK(X3)), "", MAX( 1, IF( NETWORKDAYS(W3, X3, Holiday_Dates) <= 0, 1, NETWORKDAYS(W3, X3, Holiday_Dates) - IF(W3 = X3, 0, 1) ) ) ), "" ) -> 1 | AC3: Marshalle Julluice V. Catua | AD3: 0.3557 | AE3: 91843.79 | AF3: 77.44 | AG3: Eco Protect Management Corp. | AH3: Compliant | AI3: YES | AJ3: YES | AK3: YES | AL3: YES | AN3: YES | AR3: 15882.5 | AS3: 0.5825 | AT3: 5232.36 | AU3: 0.1919 | AV3: 0 | AW3: 0 | AX3: 2320.82 | AY3: 0.1031 | AZ3: 410.73 | BA3: 0.0103 | BB3: =SUM(AS3,AU3,AW3) -> 0.7744 | BC3: =SUM(AS3,AU3,AW3) -> 0.7744 | BD3: https://embco-my.sharepoint.com/:w:/g/personal/eswmr3_emb_gov_ph/IQA5WfPi4zdFQrvzvXbj5kDRAVPSzQ2YO7TZTs8ks-501do?e=sPDram
A4: Nueva Ecija | B4: City Of Cabanatuan | C4: =CONCATENATE(A4,","," ",B4) -> Nueva Ecija, City Of Cabanatuan | D4: MBA | E4: 3rd | F4: 15.470778 | G4: 120.9521 | H4: =CONCATENATE(F4,",",G4) -> 15.470778,120.952099 | I4: Municipal / City Plan | J4: NSWMC RESO NO. 1513 SERIES OF 2022 | K4: 2020 - 2029 | L4: 2022 | M4: 2029 | O4: Christian Jem L. Buluran | Q4: Zosimo P. Suyat | R4: 1.January | S4: R3-2026-002129 | T4: 46037 | U4: 46044 | W4: 46044 | X4: 46045 | Y4: =IFERROR( IF( OR(ISBLANK(T4), ISBLANK(U4)), "", MAX( 1, IF( NETWORKDAYS(T4, U4, Holiday_Dates) <= 0, 1, NETWORKDAYS(T4, U4, Holiday_Dates) - IF(T4 = U4, 0, 1) ) ) ), "" ) -> 5 | Z4: =IF( OR(ISBLANK(U4), ISBLANK(V4)), "", MAX( 1, IF( NETWORKDAYS(U4, V4, Holiday_Dates) <= 0, 1, NETWORKDAYS(U4, V4, Holiday_Dates) - IF(U4 = V4, 0, 1) ) ) ) | AA4: =IFERROR( IF( OR(ISBLANK(W4), AND(ISBLANK(U4), ISBLANK(V4))), "", MAX( 1, IF( NETWORKDAYS(IF(NOT(ISBLANK(V4)), V4, U4), W4, Holiday_Dates) <= 0, 1, NETWORKDAYS(IF(NOT(ISBLANK(V4)), V4, U4), W4, Holiday_Dates) - IF(IF(NOT(ISBLANK(V4)), V4, U4) = W4, 0, 1) ) ) ), "" ) -> 1 | AB4: =IFERROR( IF( OR(ISBLANK(W4), ISBLANK(X4)), "", MAX( 1, IF( NETWORKDAYS(W4, X4, Holiday_Dates) <= 0, 1, NETWORKDAYS(W4, X4, Holiday_Dates) - IF(W4 = X4, 0, 1) ) ) ), "" ) -> 1 | AC4: Marshalle Julluice V. Catua | AD4: 0.363 | AE4: 136116.65 | AF4: 77.37 | AG4: Primewaste Solution Inc | AH4: Compliant | AI4: YES | AJ4: YES | AK4: YES | AL4: YES | AM4: YES | AN4: YES | AR4: 70901.2 | AS4: 0.5312 | AT4: 30538.77 | AU4: 0.2425 | AV4: 0 | AW4: 0 | AX4: 31688.62 | AY4: 0.2237 | AZ4: 345.05 | BA4: 0.0026 | BB4: =SUM(AS4,AU4,AW4) -> 0.7737 | BC4: =SUM(AS4,AU4,AW4) -> 0.7737 | BD4: https://embco-my.sharepoint.com/:w:/g/personal/eswmr3_emb_gov_ph/IQDdVVBMJoeaS6SuKSU2xPh7Af_OFDLpkLTua37NCNLCOR4?e=EmbUDA
A5: Pampanga | B5: City Of San Fernando | C5: =CONCATENATE(A5,","," ",B5) -> Pampanga, City Of San Fernando | D5: MBA | E5: 3rd | F5: 15.0279 | G5: 120.6937 | H5: =CONCATENATE(F5,",",G5) -> 15.0279,120.6937 | I5: Municipal / City Plan | J5: 167A series 2025 | K5: 2025-2034 | L5: 2025 | M5: 2034 | O5: Elyza A. Evilla | Q5: Sherwin John Y. Loquellano | R5: 1.January | S5: R3-2026-001245 | T5: 46035 | U5: 46038 | W5: 46043 | X5: 46043 | Y5: =IFERROR( IF( OR(ISBLANK(T5), ISBLANK(U5)), "", MAX( 1, IF( NETWORKDAYS(T5, U5, Holiday_Dates) <= 0, 1, NETWORKDAYS(T5, U5, Holiday_Dates) - IF(T5 = U5, 0, 1) ) ) ), "" ) -> 3 | Z5: =IF( OR(ISBLANK(U5), ISBLANK(V5)), "", MAX( 1, IF( NETWORKDAYS(U5, V5, Holiday_Dates) <= 0, 1, NETWORKDAYS(U5, V5, Holiday_Dates) - IF(U5 = V5, 0, 1) ) ) ) | AA5: =IFERROR( IF( OR(ISBLANK(W5), AND(ISBLANK(U5), ISBLANK(V5))), "", MAX( 1, IF( NETWORKDAYS(IF(NOT(ISBLANK(V5)), V5, U5), W5, Holiday_Dates) <= 0, 1, NETWORKDAYS(IF(NOT(ISBLANK(V5)), V5, U5), W5, Holiday_Dates) - IF(IF(NOT(ISBLANK(V5)), V5, U5) = W5, 0, 1) ) ) ), "" ) -> 3 | AB5: =IFERROR( IF( OR(ISBLANK(W5), ISBLANK(X5)), "", MAX( 1, IF( NETWORKDAYS(W5, X5, Holiday_Dates) <= 0, 1, NETWORKDAYS(W5, X5, Holiday_Dates) - IF(W5 = X5, 0, 1) ) ) ), "" ) -> 1 | AC5: Marshalle Julluice V. Catua | AD5: 0.637 | AE5: 255469.93 | AF5: 62.27 | AG5: Eco Protect Management Corp. | AH5: Compliant | AI5: YES | AJ5: YES | AK5: YES | AL5: YES | AM5: YES | AN5: YES | AR5: 76338.593 | AS5: 0.29882 | AT5: 82735.887 | AU5: 0.32386 | AV5: 0 | AW5: 0 | AX5: 85518.274 | AY5: 0.33475 | AZ5: 10877.176 | BA5: 0.04258 | BB5: =SUM(AS5,AU5,AW5) -> 0.62268 | BC5: =SUM(AS5,AU5,AW5) -> 0.62268 | BD5: https://embco-my.sharepoint.com/:w:/g/personal/eswmr3_emb_gov_ph/IQCyadJTiBCdTraSzEK4FCgcAaqdsntGbrIKiw5WLFauhOQ?e=vL0aPp
A6: Zambales | B6: City Of Olongapo | C6: =CONCATENATE(A6,","," ",B6) -> Zambales, City Of Olongapo | D6: OUTSIDE MBA | E6: 1st | F6: 14.842411 | G6: 120.28765 | H6: =CONCATENATE(F6,",",G6) -> 14.842411,120.287647 | I6: Municipal / City Plan | J6: NSWMC Resolution No. 1639, Series of 2023 | K6: 2023 - 2032 | L6: 2023 | M6: 2032 | O6: Larizze Ann A. Santos | Q6: Jun D. Guillermo | R6: 1.January | S6: R3-2026-001347 | T6: 46037 | U6: 46040 | W6: 46040 | X6: 46041 | Y6: =IFERROR( IF( OR(ISBLANK(T6), ISBLANK(U6)), "", MAX( 1, IF( NETWORKDAYS(T6, U6, Holiday_Dates) <= 0, 1, NETWORKDAYS(T6, U6, Holiday_Dates) - IF(T6 = U6, 0, 1) ) ) ), "" ) -> 1 | Z6: =IF( OR(ISBLANK(U6), ISBLANK(V6)), "", MAX( 1, IF( NETWORKDAYS(U6, V6, Holiday_Dates) <= 0, 1, NETWORKDAYS(U6, V6, Holiday_Dates) - IF(U6 = V6, 0, 1) ) ) ) | AA6: =IFERROR( IF( OR(ISBLANK(W6), AND(ISBLANK(U6), ISBLANK(V6))), "", MAX( 1, IF( NETWORKDAYS(IF(NOT(ISBLANK(V6)), V6, U6), W6, Holiday_Dates) <= 0, 1, NETWORKDAYS(IF(NOT(ISBLANK(V6)), V6, U6), W6, Holiday_Dates) - IF(IF(NOT(ISBLANK(V6)), V6, U6) = W6, 0, 1) ) ) ), "" ) -> 1 | AB6: =IFERROR( IF( OR(ISBLANK(W6), ISBLANK(X6)), "", MAX( 1, IF( NETWORKDAYS(W6, X6, Holiday_Dates) <= 0, 1, NETWORKDAYS(W6, X6, Holiday_Dates) - IF(W6 = X6, 0, 1) ) ) ), "" ) -> 1 | AC6: Marshalle Julluice V. Catua | AD6: 0.893 | AE6: 236558.38 | AF6: 76.84 | AG6: LGU Owned SLF | AH6: Compliant | AI6: YES | AJ6: YES | AK6: YES | AL6: YES | AN6: YES | AR6: 96468.51 | AS6: 0.4078 | AT6: 73711.59 | AU6: 0.3116 | AV6: 11591.36 | AW6: 0.049 | AX6: 47311.68 | AY6: 0.2 | AZ6: 7475.24 | BA6: 0.0316 | BB6: =SUM(AS6,AU6,AW6) -> 0.7684 | BC6: =SUM(AS6,AU6,AW6) -> 0.7684 | BD6: https://embco-my.sharepoint.com/:w:/g/personal/eswmr3_emb_gov_ph/IQCq3Z8yK6pDRY7xfHsHb-yrAfdaJkvE8BTLGFYFPAFowPU?e=OG5PVQ
A7: Tarlac | B7: Concepcion | C7: =CONCATENATE(A7,","," ",B7) -> Tarlac, Concepcion | D7: MBA | E7: 3rd | F7: 15.323352 | G7: 120.65551 | H7: =CONCATENATE(F7,",",G7) -> 15.323352,120.655511 | I7: Municipal / City Plan | J7: NSWMC RESO NO. 1404SERIES OF 2020 | K7: 2018 - 2027 | L7: 2020 | M7: 2027 | O7: Gretzhen M. Apolonio | Q7: Jan Emerson C. Gonzales | R7: 1.January | S7: R3-2026-001299 | T7: 46037 | U7: 46038 | W7: 46042 | X7: 46042 | Y7: =IFERROR( IF( OR(ISBLANK(T7), ISBLANK(U7)), "", MAX( 1, IF( NETWORKDAYS(T7, U7, Holiday_Dates) <= 0, 1, NETWORKDAYS(T7, U7, Holiday_Dates) - IF(T7 = U7, 0, 1) ) ) ), "" ) -> 1 | Z7: =IF( OR(ISBLANK(U7), ISBLANK(V7)), "", MAX( 1, IF( NETWORKDAYS(U7, V7, Holiday_Dates) <= 0, 1, NETWORKDAYS(U7, V7, Holiday_Dates) - IF(U7 = V7, 0, 1) ) ) ) | AA7: =IFERROR( IF( OR(ISBLANK(W7), AND(ISBLANK(U7), ISBLANK(V7))), "", MAX( 1, IF( NETWORKDAYS(IF(NOT(ISBLANK(V7)), V7, U7), W7, Holiday_Dates) <= 0, 1, NETWORKDAYS(IF(NOT(ISBLANK(V7)), V7, U7), W7, Holiday_Dates) - IF(IF(NOT(ISBLANK(V7)), V7, U7) = W7, 0, 1) ) ) ), "" ) -> 2 | AB7: =IFERROR( IF( OR(ISBLANK(W7), ISBLANK(X7)), "", MAX( 1, IF( NETWORKDAYS(W7, X7, Holiday_Dates) <= 0, 1, NETWORKDAYS(W7, X7, Holiday_Dates) - IF(W7 = X7, 0, 1) ) ) ), "" ) -> 1 | AC7: Marshalle Julluice V. Catua | AD7: 0.55 | AE7: 88, 316 | AF7: 85.54 | AG7: International Solid Waste Integrated Management Specialist Inc. | AH7: Compliant | AI7: YES | AJ7: YES | AK7: YES | AL7: YES | AN7: YES | AR7: 56, 725.53 | AS7: 0.6423 | AT7: 18820.19 | AU7: 0.2131 | AV7: 0 | AW7: 0 | AX7: 12726.37 | AY7: 0.1441 | AZ7: 44.16 | BA7: 0.05 | BB7: =SUM(AS7,AU7,AW7) -> 0.8554 | BC7: =SUM(AS7,AU7,AW7) -> 0.8554 | BD7: https://embco-my.sharepoint.com/:w:/g/personal/eswmr3_emb_gov_ph/IQAoXqD_P-YDQoQvY1444AYSAcRHbghpemlxV3Ql5FKXax8?e=jvcigM
A8: Aurora | B8: Maria Aurora | C8: =CONCATENATE(A8,","," ",B8) -> Aurora, Maria Aurora | D8: OUTSIDE MBA | E8: Lone | F8: 15.798717 | G8: 121.47355 | H8: =CONCATENATE(F8,",",G8) -> 15.798717,121.47355 | I8: Municipal / City Plan | J8: NSWMC Resolution No. 139, Series of 2015 | K8: 2015 - 2024 | L8: 2015 | M8: 2024 | N8: Approved | O8: Nikko Jay M. Valenzuela | Q8: Diozelle L. Cabalar | R8: 2.February | S8: R3-2026-004094 | T8: 46056 | U8: 46062 | V8: 46069 | W8: 46069 | X8: 46069 | Y8: =IFERROR( IF( OR(ISBLANK(T8), ISBLANK(U8)), "", MAX( 1, IF( NETWORKDAYS(T8, U8, Holiday_Dates) <= 0, 1, NETWORKDAYS(T8, U8, Holiday_Dates) - IF(T8 = U8, 0, 1) ) ) ), "" ) -> 4 | Z8: =IF( OR(ISBLANK(U8), ISBLANK(V8)), "", MAX( 1, IF( NETWORKDAYS(U8, V8, Holiday_Dates) <= 0, 1, NETWORKDAYS(U8, V8, Holiday_Dates) - IF(U8 = V8, 0, 1) ) ) ) -> 5 | AA8: =IFERROR( IF( OR(ISBLANK(W8), AND(ISBLANK(U8), ISBLANK(V8))), "", MAX( 1, IF( NETWORKDAYS(IF(NOT(ISBLANK(V8)), V8, U8), W8, Holiday_Dates) <= 0, 1, NETWORKDAYS(IF(NOT(ISBLANK(V8)), V8, U8), W8, Holiday_Dates) - IF(IF(NOT(ISBLANK(V8)), V8, U8) = W8, 0, 1) ) ) ), "" ) -> 1 | AB8: =IFERROR( IF( OR(ISBLANK(W8), ISBLANK(X8)), "", MAX( 1, IF( NETWORKDAYS(W8, X8, Holiday_Dates) <= 0, 1, NETWORKDAYS(W8, X8, Holiday_Dates) - IF(W8 = X8, 0, 1) ) ) ), "" ) -> 1 | AC8: Marshalle Julluice V. Catua | AD8: 0.24 | AE8: 1846.31 | AF8: 8.02 | AG8: Maria Aurora SLF | AH8: Compliant | AI8: YES | AJ8: YES | AK8: YES | AL8: YES | AN8: YES | AR8: 95.66 | AS8: 0.0518 | AT8: 39.14 | AU8: 0.0211 | AV8: 13.58 | AW8: 0.0073 | AX8: 1697.93 | AY8: 0.9196 | AZ8: 0 | BA8: 0 | BB8: =SUM(AS8,AU8,AW8) -> 0.0802 | BC8: =SUM(AS8,AU8,AW8) -> 0.0802 | BD8: https://embco-my.sharepoint.com/:w:/g/personal/eswmr3_emb_gov_ph/IQBIG2IIMgPxTo3UTdguNmkXAY9AMq8I2bvdPXit5HIiqhw?e=ukKJuY
A9: Bataan | B9: Bagac | C9: =CONCATENATE(A9,","," ",B9) -> Bataan, Bagac | D9: MBA | E9: 3rd | F9: 14.607148 | G9: 120.402 | H9: =CONCATENATE(F9,",",G9) -> 14.607148,120.401997 | I9: Municipal / City Plan | J9: 975 SERIES OF 2017 | K9: 2015 - 2024 | L9: 2017 | M9: 2024 | N9: For Renewal | O9: Laurence Radasa | Q9: Christle D. David | R9: 2.February | S9: R3-2026-004255 | T9: 46062 | U9: 46063 | W9: 46064 | X9: 46064 | Y9: =IFERROR( IF( OR(ISBLANK(T9), ISBLANK(U9)), "", MAX( 1, IF( NETWORKDAYS(T9, U9, Holiday_Dates) <= 0, 1, NETWORKDAYS(T9, U9, Holiday_Dates) - IF(T9 = U9, 0, 1) ) ) ), "" ) -> 1 | Z9: =IF( OR(ISBLANK(U9), ISBLANK(V9)), "", MAX( 1, IF( NETWORKDAYS(U9, V9, Holiday_Dates) <= 0, 1, NETWORKDAYS(U9, V9, Holiday_Dates) - IF(U9 = V9, 0, 1) ) ) ) | AA9: =IFERROR( IF( OR(ISBLANK(W9), AND(ISBLANK(U9), ISBLANK(V9))), "", MAX( 1, IF( NETWORKDAYS(IF(NOT(ISBLANK(V9)), V9, U9), W9, Holiday_Dates) <= 0, 1, NETWORKDAYS(IF(NOT(ISBLANK(V9)), V9, U9), W9, Holiday_Dates) - IF(IF(NOT(ISBLANK(V9)), V9, U9) = W9, 0, 1) ) ) ), "" ) -> 1 | AB9: =IFERROR( IF( OR(ISBLANK(W9), ISBLANK(X9)), "", MAX( 1, IF( NETWORKDAYS(W9, X9, Holiday_Dates) <= 0, 1, NETWORKDAYS(W9, X9, Holiday_Dates) - IF(W9 = X9, 0, 1) ) ) ), "" ) -> 1 | AC9: Marshalle Julluice V. Catua | AD9: 0.404 | AE9: 11865.24 | AF9: 91.16 | AG9: Eco Protect Management Corporation Floridablanca Enviro Corporation | AH9: Compliant | AI9: YES | AJ9: YES | AK9: YES | AL9: YES | AM9: YES | AN9: YES | AR9: 6555.54 | AS9: 0.5525 | AT9: 3141.92 | AU9: 0.2648 | AV9: 1118.89 | AW9: 0.0943 | AX9: 1035.84 | AY9: 0.0873 | AZ9: 13.05 | BA9: 0.0011 | BB9: =SUM(AS9,AU9,AW9) -> 0.9116 | BC9: =SUM(AS9,AU9,AW9) -> 0.9116 | BD9: https://embco-my.sharepoint.com/:w:/g/personal/eswmr3_emb_gov_ph/IQBQM3HpC3GtQLTiWy-TFxP4AZLt3PRtwRxxBpO5-qYEMhk?e=W0qafE
A10: Bataan | B10: City Of Balanga | C10: =CONCATENATE(A10,","," ",B10) -> Bataan, City Of Balanga | D10: MBA | E10: 2nd | F10: 14.679914 | G10: 120.5407 | H10: =CONCATENATE(F10,",",G10) -> 14.679914,120.540698 | I10: Municipal / City Plan | J10: 482-A series of 2025 | K10: 2025-2034 | L10: 2025 | M10: 2034 | N10: For Renewal | O10: Dennis Tolentino | Q10: Christle D. David | R10: 2.February | S10: R3-2026-002980 | T10: 46051 | U10: 46052 | W10: 46053 | X10: 46055 | Y10: =IFERROR( IF( OR(ISBLANK(T10), ISBLANK(U10)), "", MAX( 1, IF( NETWORKDAYS(T10, U10, Holiday_Dates) <= 0, 1, NETWORKDAYS(T10, U10, Holiday_Dates) - IF(T10 = U10, 0, 1) ) ) ), "" ) -> 1 | Z10: =IF( OR(ISBLANK(U10), ISBLANK(V10)), "", MAX( 1, IF( NETWORKDAYS(U10, V10, Holiday_Dates) <= 0, 1, NETWORKDAYS(U10, V10, Holiday_Dates) - IF(U10 = V10, 0, 1) ) ) ) | AA10: =IFERROR( IF( OR(ISBLANK(W10), AND(ISBLANK(U10), ISBLANK(V10))), "", MAX( 1, IF( NETWORKDAYS(IF(NOT(ISBLANK(V10)), V10, U10), W10, Holiday_Dates) <= 0, 1, NETWORKDAYS(IF(NOT(ISBLANK(V10)), V10, U10), W10, Holiday_Dates) - IF(IF(NOT(ISBLANK(V10)), V10, U10) = W10, 0, 1) ) ) ), "" ) -> 1 | AB10: =IFERROR( IF( OR(ISBLANK(W10), ISBLANK(X10)), "", MAX( 1, IF( NETWORKDAYS(W10, X10, Holiday_Dates) <= 0, 1, NETWORKDAYS(W10, X10, Holiday_Dates) - IF(W10 = X10, 0, 1) ) ) ), "" ) -> 1 | AC10: Marshalle Julluice V. Catua | AD10: 0.485 | AE10: 50572.4 | AF10: 80.88 | AG10: BEST | AH10: Compliant | AI10: YES | AJ10: YES | AK10: YES | AL10: YES | AN10: YES | AR10: 19505.77 | AS10: 0.3857 | AT10: 9118.2 | AU10: 0.1803 | AV10: 12279.67 | AW10: 0.2428 | AX10: 9117.51 | AY10: 0.1803 | AZ10: 551.25 | BA10: 0.0109 | BB10: =SUM(AS10,AU10,AW10) -> 0.8088 | BC10: =SUM(AS10,AU10,AW10) -> 0.8088 | BD10: https://embco-my.sharepoint.com/:w:/g/personal/eswmr3_emb_gov_ph/IQAgMCluM58-SqQi5zpZbqF0AXvustCA0W3GmUhPUmg582k?e=gilkhF
A11: Bulacan | B11: City Of Meycauayan | C11: =CONCATENATE(A11,","," ",B11) -> Bulacan, City Of Meycauayan | D11: MBA | E11: 4th | F11: 14.774921 | G11: 120.99868 | H11: =CONCATENATE(F11,",",G11) -> 14.774921,120.998685 | I11: Municipal / City Plan | J11: NSWMC RESO NO. 1326 SERIES OF 2019 | K11: 2018 -2028 | L11: 2019 | M11: 2028 | N11: For Renewal | O11: James Wilson T. Pena | Q11: Diozelle L. Cabalar | R11: 2.February | S11: R3-2026-005241 | T11: 46069 | U11: 46070 | W11: 46071 | X11: 46071 | Y11: =IFERROR( IF( OR(ISBLANK(T11), ISBLANK(U11)), "", MAX( 1, IF( NETWORKDAYS(T11, U11, Holiday_Dates) <= 0, 1, NETWORKDAYS(T11, U11, Holiday_Dates) - IF(T11 = U11, 0, 1) ) ) ), "" ) -> 1 | Z11: =IF( OR(ISBLANK(U11), ISBLANK(V11)), "", MAX( 1, IF( NETWORKDAYS(U11, V11, Holiday_Dates) <= 0, 1, NETWORKDAYS(U11, V11, Holiday_Dates) - IF(U11 = V11, 0, 1) ) ) ) | AA11: =IFERROR( IF( OR(ISBLANK(W11), AND(ISBLANK(U11), ISBLANK(V11))), "", MAX( 1, IF( NETWORKDAYS(IF(NOT(ISBLANK(V11)), V11, U11), W11, Holiday_Dates) <= 0, 1, NETWORKDAYS(IF(NOT(ISBLANK(V11)), V11, U11), W11, Holiday_Dates) - IF(IF(NOT(ISBLANK(V11)), V11, U11) = W11, 0, 1) ) ) ), "" ) -> 1 | AB11: =IFERROR( IF( OR(ISBLANK(W11), ISBLANK(X11)), "", MAX( 1, IF( NETWORKDAYS(W11, X11, Holiday_Dates) <= 0, 1, NETWORKDAYS(W11, X11, Holiday_Dates) - IF(W11 = X11, 0, 1) ) ) ), "" ) -> 1 | AC11: Retuned to Focal | AD11: 0.255 | AE11: 34696.32 | AF11: 60.86 | AG11: ISWIMS SLF, Montalban, Rizal | AH11: Compliant | AI11: YES | AJ11: YES | AK11: YES | AL11: YES | AM11: NO | AN11: YES | AR11: 15882.5 | AS11: 0.5825 | AT11: 5232.36 | AU11: 0.1919 | AV11: 0 | AW11: 0 | AX11: 2320.82 | AY11: 0.1031 | AZ11: 410.73 | BA11: 0.0103 | BB11: =SUM(AS11,AU11,AW11) -> 0.7744 | BC11: =SUM(AS11,AU11,AW11) -> 0.7744 | BD11: https://embco-my.sharepoint.com/:w:/g/personal/eswmr3_emb_gov_ph/IQCAVxiIc-99TaOdfKCj2l4zAQKMPl3igA2xNSpjL7qjuWg?e=bJ3gJI
A12: Bulacan | B12: Plaridel | C12: =CONCATENATE(A12,","," ",B12) -> Bulacan, Plaridel | D12: MBA | E12: 2nd | F12: 14.886807 | G12: 120.85987 | H12: =CONCATENATE(F12,",",G12) -> 14.88680651,120.8598685 | I12: Municipal / City Plan | J12: 157-A Series of 2025 | K12: 2025-2034 | L12: 2025 | M12: 2034 | O12: Jasmin Marie N. Siapco | Q12: Diozelle L. Cabalar | R12: 2.February | S12: R3-2026-003662 | T12: 46057 | U12: 46058 | W12: 46067 | X12: 46069 | Y12: =IFERROR( IF( OR(ISBLANK(T12), ISBLANK(U12)), "", MAX( 1, IF( NETWORKDAYS(T12, U12, Holiday_Dates) <= 0, 1, NETWORKDAYS(T12, U12, Holiday_Dates) - IF(T12 = U12, 0, 1) ) ) ), "" ) -> 1 | Z12: =IF( OR(ISBLANK(U12), ISBLANK(V12)), "", MAX( 1, IF( NETWORKDAYS(U12, V12, Holiday_Dates) <= 0, 1, NETWORKDAYS(U12, V12, Holiday_Dates) - IF(U12 = V12, 0, 1) ) ) ) | AA12: =IFERROR( IF( OR(ISBLANK(W12), AND(ISBLANK(U12), ISBLANK(V12))), "", MAX( 1, IF( NETWORKDAYS(IF(NOT(ISBLANK(V12)), V12, U12), W12, Holiday_Dates) <= 0, 1, NETWORKDAYS(IF(NOT(ISBLANK(V12)), V12, U12), W12, Holiday_Dates) - IF(IF(NOT(ISBLANK(V12)), V12, U12) = W12, 0, 1) ) ) ), "" ) -> 6 | AB12: =IFERROR( IF( OR(ISBLANK(W12), ISBLANK(X12)), "", MAX( 1, IF( NETWORKDAYS(W12, X12, Holiday_Dates) <= 0, 1, NETWORKDAYS(W12, X12, Holiday_Dates) - IF(W12 = X12, 0, 1) ) ) ), "" ) -> 1 | AC12: Marshalle Julluice V. Catua | AD12: 0.329 | AE12: 39066.71 | AF12: 78.02 | AG12: Eco Protect Management Corporation | AH12: Compliant | AI12: YES | AJ12: YES | AK12: YES | AL12: YES | AN12: YES | AR12: 21694.27 | AS12: 0.5553 | AT12: 8832.99 | AU12: 0.2261 | AV12: 0 | AW12: 0 | AX12: 7846.2 | AY12: 0.2008 | AZ12: 693.27 | BA12: 0.0177 | BB12: =SUM(AS12,AU12,AW12) -> 0.7814 | BC12: =SUM(AS12,AU12,AW12) -> 0.7814 | BD12: https://embco-my.sharepoint.com/:w:/g/personal/eswmr3_emb_gov_ph/IQAHn3vp5f4nQrQ43iUpqvvmAU99LfYW1ONFGthYz21oHfE?e=hWfGHC
A13: Nueva Ecija | B13: Gen. Natividad | C13: =CONCATENATE(A13,","," ",B13) -> Nueva Ecija, Gen. Natividad | D13: MBA | E13: 3rd | F13: 15.602761 | G13: 121.04995 | H13: =CONCATENATE(F13,",",G13) -> 15.602761,121.049951 | I13: Municipal / City Plan | J13: 1076 series 2018 | K13: 2017 - 2027 | L13: 2018 | M13: 2027 | O13: Hosannah R. Sabio | Q13: Zosimo P. Suyat | R13: 2.February | S13: R3-2026-005353 | T13: 46069 | U13: 46071 | W13: 46071 | X13: 46071 | Y13: =IFERROR( IF( OR(ISBLANK(T13), ISBLANK(U13)), "", MAX( 1, IF( NETWORKDAYS(T13, U13, Holiday_Dates) <= 0, 1, NETWORKDAYS(T13, U13, Holiday_Dates) - IF(T13 = U13, 0, 1) ) ) ), "" ) -> 2 | Z13: =IF( OR(ISBLANK(U13), ISBLANK(V13)), "", MAX( 1, IF( NETWORKDAYS(U13, V13, Holiday_Dates) <= 0, 1, NETWORKDAYS(U13, V13, Holiday_Dates) - IF(U13 = V13, 0, 1) ) ) ) | AA13: =IFERROR( IF( OR(ISBLANK(W13), AND(ISBLANK(U13), ISBLANK(V13))), "", MAX( 1, IF( NETWORKDAYS(IF(NOT(ISBLANK(V13)), V13, U13), W13, Holiday_Dates) <= 0, 1, NETWORKDAYS(IF(NOT(ISBLANK(V13)), V13, U13), W13, Holiday_Dates) - IF(IF(NOT(ISBLANK(V13)), V13, U13) = W13, 0, 1) ) ) ), "" ) -> 1 | AB13: =IFERROR( IF( OR(ISBLANK(W13), ISBLANK(X13)), "", MAX( 1, IF( NETWORKDAYS(W13, X13, Holiday_Dates) <= 0, 1, NETWORKDAYS(W13, X13, Holiday_Dates) - IF(W13 = X13, 0, 1) ) ) ), "" ) -> 1 | AC13: Marshalle Julluice V. Catua | AD13: 0.25 | AE13: 10690 | AF13: 91.25 | AG13: Prime Waste Solution | AH13: Compliant | AI13: YES | AJ13: YES | AK13: YES | AL13: YES | AN13: YES | AR13: 6812.11 | AS13: 0.6095 | AT13: 3386.05 | AU13: 0.303 | AV13: 0 | AW13: 0 | AX13: 527.12 | AY13: 0.0472 | AZ13: 450.85 | BA13: 0.0403 | BB13: =SUM(AS13,AU13,AW13) -> 0.9125 | BC13: =SUM(AS13,AU13,AW13) -> 0.9125 | BD13: https://embco-my.sharepoint.com/:w:/g/personal/eswmr3_emb_gov_ph/IQB2HswZFbenQJlrQ5OvuLOhAUT0Ob9KeuZppjA1rXhA2X4?e=0xDsQ8
A14: Nueva Ecija | B14: Lupao | C14: =CONCATENATE(A14,","," ",B14) -> Nueva Ecija, Lupao | D14: MBA | E14: 2nd | F14: 15.877262 | G14: 120.8989 | H14: =CONCATENATE(F14,",",G14) -> 15.877262,120.898901 | I14: Municipal / City Plan | J14: 1065 Series of 2018 | K14: 2017 - 2026 | L14: 2018 | M14: 2026 | O14: Aser A. Inocencio, Jr. | Q14: Zosimo P. Suyat | R14: 2.February | S14: R3-2026-005457 | T14: 46071 | U14: 46071 | W14: 46072 | X14: 46072 | Y14: =IFERROR( IF( OR(ISBLANK(T14), ISBLANK(U14)), "", MAX( 1, IF( NETWORKDAYS(T14, U14, Holiday_Dates) <= 0, 1, NETWORKDAYS(T14, U14, Holiday_Dates) - IF(T14 = U14, 0, 1) ) ) ), "" ) -> 1 | Z14: =IF( OR(ISBLANK(U14), ISBLANK(V14)), "", MAX( 1, IF( NETWORKDAYS(U14, V14, Holiday_Dates) <= 0, 1, NETWORKDAYS(U14, V14, Holiday_Dates) - IF(U14 = V14, 0, 1) ) ) ) | AA14: =IFERROR( IF( OR(ISBLANK(W14), AND(ISBLANK(U14), ISBLANK(V14))), "", MAX( 1, IF( NETWORKDAYS(IF(NOT(ISBLANK(V14)), V14, U14), W14, Holiday_Dates) <= 0, 1, NETWORKDAYS(IF(NOT(ISBLANK(V14)), V14, U14), W14, Holiday_Dates) - IF(IF(NOT(ISBLANK(V14)), V14, U14) = W14, 0, 1) ) ) ), "" ) -> 1 | AB14: =IFERROR( IF( OR(ISBLANK(W14), ISBLANK(X14)), "", MAX( 1, IF( NETWORKDAYS(W14, X14, Holiday_Dates) <= 0, 1, NETWORKDAYS(W14, X14, Holiday_Dates) - IF(W14 = X14, 0, 1) ) ) ), "" ) -> 1 | AC14: Marshalle Julluice V. Catua | AD14: 0.605 | AE14: 28913.11 | AF14: 85.52 | AG14: Metro Waste Solid Waste Management Corporation | AH14: Compliant | AI14: YES | AJ14: YES | AK14: YES | AL14: YES | AM14: YES | AN14: YES | AR14: 17920.35 | AS14: 0.6198 | AT14: 5195.69 | AU14: 0.1797 | AV14: 1610.46 | AW14: 0.0557 | AX14: 3619.92 | AY14: 0.1252 | AZ14: 556.7 | BA14: 0.0196 | BB14: =SUM(AS14,AU14,AW14) -> 0.8552 | BC14: =SUM(AS14,AU14,AW14) -> 0.8552 | BD14: https://embco-my.sharepoint.com/:w:/g/personal/eswmr3_emb_gov_ph/IQCwaDpqubn3TYH_bx42jlxwAVkivze19aAPwXpraCl-68g?e=uTdsI3
A15: Nueva Ecija | B15: San Antonio_N | C15: =CONCATENATE(A15,","," ",B15) -> Nueva Ecija, San Antonio_N | D15: MBA | E15: 4th | F15: 15.306809 | G15: 120.85671 | H15: =CONCATENATE(F15,",",G15) -> 15.306809,120.856712 | I15: Municipal / City Plan | J15: NSWMC RESO NO. 1490 SERIES OF 2021 | K15: 2020 - 2029 | L15: 2021 | M15: 2029 | O15: Christine Ann V. Ramos | Q15: Zosimo P. Suyat | R15: 2.February | S15: R3-2026-004721 | T15: 46065 | U15: 46066 | W15: 46071 | X15: 46071 | Y15: =IFERROR( IF( OR(ISBLANK(T15), ISBLANK(U15)), "", MAX( 1, IF( NETWORKDAYS(T15, U15, Holiday_Dates) <= 0, 1, NETWORKDAYS(T15, U15, Holiday_Dates) - IF(T15 = U15, 0, 1) ) ) ), "" ) -> 1 | Z15: =IF( OR(ISBLANK(U15), ISBLANK(V15)), "", MAX( 1, IF( NETWORKDAYS(U15, V15, Holiday_Dates) <= 0, 1, NETWORKDAYS(U15, V15, Holiday_Dates) - IF(U15 = V15, 0, 1) ) ) ) | AA15: =IFERROR( IF( OR(ISBLANK(W15), AND(ISBLANK(U15), ISBLANK(V15))), "", MAX( 1, IF( NETWORKDAYS(IF(NOT(ISBLANK(V15)), V15, U15), W15, Holiday_Dates) <= 0, 1, NETWORKDAYS(IF(NOT(ISBLANK(V15)), V15, U15), W15, Holiday_Dates) - IF(IF(NOT(ISBLANK(V15)), V15, U15) = W15, 0, 1) ) ) ), "" ) -> 3 | AB15: =IFERROR( IF( OR(ISBLANK(W15), ISBLANK(X15)), "", MAX( 1, IF( NETWORKDAYS(W15, X15, Holiday_Dates) <= 0, 1, NETWORKDAYS(W15, X15, Holiday_Dates) - IF(W15 = X15, 0, 1) ) ) ), "" ) -> 1 | AC15: Marshalle Julluice V. Catua | AD15: 0.629 | AE15: 54017.28 | AF15: 84.18 | AG15: Urdaneta Waste Management | AH15: Compliant | AI15: YES | AJ15: YES | AK15: YES | AL15: YES | AN15: YES | AR15: 30562.98 | AS15: 0.5658 | AT15: 12180.9 | AU15: 0.2255 | AV15: 2727.87 | AW15: 0.0505 | AX15: 8415.89 | AY15: 0.1558 | AZ15: 129.64 | BA15: 0.24 | BB15: =SUM(AS15,AU15,AW15) -> 0.8418 | BC15: =SUM(AS15,AU15,AW15) -> 0.8418 | BD15: https://embco-my.sharepoint.com/:w:/g/personal/eswmr3_emb_gov_ph/IQDp0hTYADdoS5Hr2gs2pslnATByESpmqmHy-VmQpc7i-Yo?e=oS6hRb
A16: Pampanga | B16: City Of Angeles | C16: =CONCATENATE(A16,","," ",B16) -> Pampanga, City Of Angeles | D16: MBA | E16: 1st | F16: 15.1653 | G16: 120.6084 | H16: =CONCATENATE(F16,",",G16) -> 15.1653,120.6084 | I16: Municipal / City Plan | J16: NSWMC RESO NO. 196 SERIES OF 2015 | K16: 2015 - 2024 | L16: 2015 | M16: 2024 | N16: For Renewal | O16: Elyza A. Evilla | Q16: Sherwin John Y. Loquellano | R16: 2.February | S16: R3-2026-005383 | T16: 46069 | U16: 46071 | W16: 46071 | X16: 46071 | Y16: =IFERROR( IF( OR(ISBLANK(T16), ISBLANK(U16)), "", MAX( 1, IF( NETWORKDAYS(T16, U16, Holiday_Dates) <= 0, 1, NETWORKDAYS(T16, U16, Holiday_Dates) - IF(T16 = U16, 0, 1) ) ) ), "" ) -> 2 | Z16: =IF( OR(ISBLANK(U16), ISBLANK(V16)), "", MAX( 1, IF( NETWORKDAYS(U16, V16, Holiday_Dates) <= 0, 1, NETWORKDAYS(U16, V16, Holiday_Dates) - IF(U16 = V16, 0, 1) ) ) ) | AA16: =IFERROR( IF( OR(ISBLANK(W16), AND(ISBLANK(U16), ISBLANK(V16))), "", MAX( 1, IF( NETWORKDAYS(IF(NOT(ISBLANK(V16)), V16, U16), W16, Holiday_Dates) <= 0, 1, NETWORKDAYS(IF(NOT(ISBLANK(V16)), V16, U16), W16, Holiday_Dates) - IF(IF(NOT(ISBLANK(V16)), V16, U16) = W16, 0, 1) ) ) ), "" ) -> 1 | AB16: =IFERROR( IF( OR(ISBLANK(W16), ISBLANK(X16)), "", MAX( 1, IF( NETWORKDAYS(W16, X16, Holiday_Dates) <= 0, 1, NETWORKDAYS(W16, X16, Holiday_Dates) - IF(W16 = X16, 0, 1) ) ) ), "" ) -> 1 | AC16: Marshalle Julluice V. Catua | AD16: 0.31 | AE16: 456827.24 | AF16: 62.01 | AG16: Eco Protect Management Corp | AH16: Non Compliant | AI16: YES | AJ16: YES | AK16: YES | AM16: YES | AN16: YES | AR16: 154629.9 | AS16: 0.3385 | AT16: 128659.89 | AU16: 0.2816 | AV16: 0 | AW16: 0 | AX16: 167568.18 | AY16: 0.3668 | AZ16: 5969.29 | BA16: 0.0131 | BB16: =SUM(AS16,AU16,AW16) -> 0.6201 | BC16: =SUM(AS16,AU16,AW16) -> 0.6201 | BD16: https://embco-my.sharepoint.com/:w:/g/personal/eswmr3_emb_gov_ph/IQCOPFe6Yq9yQq33emuhsx8bAXsrfWBFLLqp4Xok8WBmUNk?e=SqsoGj
A17: Pampanga | B17: Masantol | C17: =CONCATENATE(A17,","," ",B17) -> Pampanga, Masantol | D17: MBA | E17: 4th | F17: 14.8925 | G17: 120.7053 | H17: =CONCATENATE(F17,",",G17) -> 14.8925,120.7053 | I17: Municipal / City Plan | J17: 1028-A series of 2019 | K17: 2014 - 2024 | L17: 2019 | M17: 2024 | N17: For Renewal | O17: Glaiza S.Gaza | Q17: Sherwin John Y. Loquellano | R17: 2.February | S17: R3-2026-005179 | T17: 46069 | U17: 46069 | W17: 46071 | X17: 46071 | Y17: =IFERROR( IF( OR(ISBLANK(T17), ISBLANK(U17)), "", MAX( 1, IF( NETWORKDAYS(T17, U17, Holiday_Dates) <= 0, 1, NETWORKDAYS(T17, U17, Holiday_Dates) - IF(T17 = U17, 0, 1) ) ) ), "" ) -> 1 | Z17: =IF( OR(ISBLANK(U17), ISBLANK(V17)), "", MAX( 1, IF( NETWORKDAYS(U17, V17, Holiday_Dates) <= 0, 1, NETWORKDAYS(U17, V17, Holiday_Dates) - IF(U17 = V17, 0, 1) ) ) ) | AA17: =IFERROR( IF( OR(ISBLANK(W17), AND(ISBLANK(U17), ISBLANK(V17))), "", MAX( 1, IF( NETWORKDAYS(IF(NOT(ISBLANK(V17)), V17, U17), W17, Holiday_Dates) <= 0, 1, NETWORKDAYS(IF(NOT(ISBLANK(V17)), V17, U17), W17, Holiday_Dates) - IF(IF(NOT(ISBLANK(V17)), V17, U17) = W17, 0, 1) ) ) ), "" ) -> 2 | AB17: =IFERROR( IF( OR(ISBLANK(W17), ISBLANK(X17)), "", MAX( 1, IF( NETWORKDAYS(W17, X17, Holiday_Dates) <= 0, 1, NETWORKDAYS(W17, X17, Holiday_Dates) - IF(W17 = X17, 0, 1) ) ) ), "" ) -> 1 | AC17: Marshalle Julluice V. Catua | AD17: 0.524 | AE17: 32231.17 | AF17: 69.05 | AG17: Floridablanca Enviro Corp. | AH17: Non Compliant | AI17: NO | AJ17: NO | AK17: NO | AL17: YES | AM17: YES | AN17: YES | AR17: 11163.39 | AS17: 0.3464 | AT17: 11090.75 | AU17: 0.3441 | AV17: 0 | AW17: 0 | AX17: 9200.44 | AY17: 0.2854 | AZ17: 776.59 | BA17: 0.0241 | BB17: =SUM(AS17,AU17,AW17) -> 0.6905 | BC17: =SUM(AS17,AU17,AW17) -> 0.6905 | BD17: https://embco-my.sharepoint.com/:w:/g/personal/eswmr3_emb_gov_ph/IQCCMRVJHkFtTpBAW4auNqw0AeoYIbp0vUlDQI8y7u51Nu0?e=hpwmc6
A18: Tarlac | B18: La Paz | C18: =CONCATENATE(A18,","," ",B18) -> Tarlac, La Paz | D18: MBA | E18: 3rd | F18: 15.44117 | G18: 120.72953 | H18: =CONCATENATE(F18,",",G18) -> 15.44117,120.729534 | I18: Municipal / City Plan | J18: 141, series of 2015 | K18: 2014 - 2023 | L18: 2015 | M18: 2023 | N18: For Renewal | O18: Gretzhen M. Apolonio | Q18: Jan Emerson C. Gonzales | R18: 2.February | S18: R3-2026-005180 | T18: 46056 | U18: 46069 | W18: 46071 | X18: 46071 | Y18: =IFERROR( IF( OR(ISBLANK(T18), ISBLANK(U18)), "", MAX( 1, IF( NETWORKDAYS(T18, U18, Holiday_Dates) <= 0, 1, NETWORKDAYS(T18, U18, Holiday_Dates) - IF(T18 = U18, 0, 1) ) ) ), "" ) -> 9 | Z18: =IF( OR(ISBLANK(U18), ISBLANK(V18)), "", MAX( 1, IF( NETWORKDAYS(U18, V18, Holiday_Dates) <= 0, 1, NETWORKDAYS(U18, V18, Holiday_Dates) - IF(U18 = V18, 0, 1) ) ) ) | AA18: =IFERROR( IF( OR(ISBLANK(W18), AND(ISBLANK(U18), ISBLANK(V18))), "", MAX( 1, IF( NETWORKDAYS(IF(NOT(ISBLANK(V18)), V18, U18), W18, Holiday_Dates) <= 0, 1, NETWORKDAYS(IF(NOT(ISBLANK(V18)), V18, U18), W18, Holiday_Dates) - IF(IF(NOT(ISBLANK(V18)), V18, U18) = W18, 0, 1) ) ) ), "" ) -> 2 | AB18: =IFERROR( IF( OR(ISBLANK(W18), ISBLANK(X18)), "", MAX( 1, IF( NETWORKDAYS(W18, X18, Holiday_Dates) <= 0, 1, NETWORKDAYS(W18, X18, Holiday_Dates) - IF(W18 = X18, 0, 1) ) ) ), "" ) -> 1 | AC18: Marshalle Julluice V. Catua | AD18: 0.33 | AE18: 25689.84 | AF18: 92 | AG18: MAA Integrated Solid Waste Management Corporation | AH18: Compliant | AI18: YES | AJ18: YES | AK18: YES | AL18: YES | AM18: YES | AN18: YES | AR18: 16376.51 | AS18: 0.6375 | AT18: 2761.53 | AU18: 0.1075 | AV18: 0 | AW18: 0 | AX18: 6260.98 | AY18: 0.2437 | AZ18: 290.82 | BA18: 0.0113 | BB18: =SUM(AS18,AU18,AW18) -> 0.745 | BC18: =SUM(AS18,AU18,AW18) -> 0.745 | BD18: https://embco-my.sharepoint.com/:w:/g/personal/eswmr3_emb_gov_ph/IQC2wZmNbmAaQLYiw7lc9fm5AR_UaEKllCj6-Vb4kUh389w?e=zQb5xZ
A19: Tarlac | B19: Moncada | C19: =CONCATENATE(A19,","," ",B19) -> Tarlac, Moncada | D19: OUTSIDE MBA | E19: 1st | F19: 15.733045 | G19: 120.5727 | H19: =CONCATENATE(F19,",",G19) -> 15.7330446,120.5727025 | I19: Municipal / City Plan | J19: NSWMC Resolution No. 237-A | K19: 2025 - 2034 | L19: 2025 | M19: 2034 | N19: Approved | O19: Joshua A. Capones | Q19: Jan Emerson C. Gonzales | R19: 2.February | S19: R3-2026-003829 | T19: 46057 | U19: 46059 | W19: 46069 | X19: 46069 | Y19: =IFERROR( IF( OR(ISBLANK(T19), ISBLANK(U19)), "", MAX( 1, IF( NETWORKDAYS(T19, U19, Holiday_Dates) <= 0, 1, NETWORKDAYS(T19, U19, Holiday_Dates) - IF(T19 = U19, 0, 1) ) ) ), "" ) -> 2 | Z19: =IF( OR(ISBLANK(U19), ISBLANK(V19)), "", MAX( 1, IF( NETWORKDAYS(U19, V19, Holiday_Dates) <= 0, 1, NETWORKDAYS(U19, V19, Holiday_Dates) - IF(U19 = V19, 0, 1) ) ) ) | AA19: =IFERROR( IF( OR(ISBLANK(W19), AND(ISBLANK(U19), ISBLANK(V19))), "", MAX( 1, IF( NETWORKDAYS(IF(NOT(ISBLANK(V19)), V19, U19), W19, Holiday_Dates) <= 0, 1, NETWORKDAYS(IF(NOT(ISBLANK(V19)), V19, U19), W19, Holiday_Dates) - IF(IF(NOT(ISBLANK(V19)), V19, U19) = W19, 0, 1) ) ) ), "" ) -> 6 | AB19: =IFERROR( IF( OR(ISBLANK(W19), ISBLANK(X19)), "", MAX( 1, IF( NETWORKDAYS(W19, X19, Holiday_Dates) <= 0, 1, NETWORKDAYS(W19, X19, Holiday_Dates) - IF(W19 = X19, 0, 1) ) ) ), "" ) -> 1 | AC19: Marshalle Julluice V. Catua | AD19: 0.72 | AE19: 50250.96 | AF19: 74.5 | AG19: MAA Integrated Solid Waste Management Corporation | AH19: Compliant | AI19: YES | AJ19: YES | AK19: YES | AL19: YES | AN19: YES | AR19: 23808.9 | AS19: 0.4738 | AT19: 13025.25 | AU19: 0.2592 | AV19: 351.76 | AW19: 0.007 | AX19: 6260.98 | AY19: 0.2437 | AZ19: 462.31 | BA19: 0.0288 | BB19: =SUM(AS19,AU19,AW19) -> 0.74 | BC19: =SUM(AS19,AU19,AW19) -> 0.74 | BD19: https://embco-my.sharepoint.com/:w:/g/personal/eswmr3_emb_gov_ph/IQDbaHxfL6VJR4M9sCxscKgRAQPjPXK81XVQK8jD1sItViE?e=DMh4KK
A20: Zambales | B20: Botolan | C20: =CONCATENATE(A20,","," ",B20) -> Zambales, Botolan | D20: OUTSIDE MBA | E20: 2nd | F20: 15.288611 | G20: 120.02333 | H20: =CONCATENATE(F20,",",G20) -> 15.288611,120.023333 | I20: Municipal / City Plan | J20: No. 1415 Series of 2020 | K20: 2019 - 2029 | L20: 2020 | M20: 2029 | O20: Larizze A. Santos | Q20: Jun D. Guillermo | R20: 2.February | S20: R3-2026-005273 | T20: 46069 | U20: 46071 | W20: 46071 | X20: 46071 | Y20: =IFERROR( IF( OR(ISBLANK(T20), ISBLANK(U20)), "", MAX( 1, IF( NETWORKDAYS(T20, U20, Holiday_Dates) <= 0, 1, NETWORKDAYS(T20, U20, Holiday_Dates) - IF(T20 = U20, 0, 1) ) ) ), "" ) -> 2 | Z20: =IF( OR(ISBLANK(U20), ISBLANK(V20)), "", MAX( 1, IF( NETWORKDAYS(U20, V20, Holiday_Dates) <= 0, 1, NETWORKDAYS(U20, V20, Holiday_Dates) - IF(U20 = V20, 0, 1) ) ) ) | AA20: =IFERROR( IF( OR(ISBLANK(W20), AND(ISBLANK(U20), ISBLANK(V20))), "", MAX( 1, IF( NETWORKDAYS(IF(NOT(ISBLANK(V20)), V20, U20), W20, Holiday_Dates) <= 0, 1, NETWORKDAYS(IF(NOT(ISBLANK(V20)), V20, U20), W20, Holiday_Dates) - IF(IF(NOT(ISBLANK(V20)), V20, U20) = W20, 0, 1) ) ) ), "" ) -> 1 | AB20: =IFERROR( IF( OR(ISBLANK(W20), ISBLANK(X20)), "", MAX( 1, IF( NETWORKDAYS(W20, X20, Holiday_Dates) <= 0, 1, NETWORKDAYS(W20, X20, Holiday_Dates) - IF(W20 = X20, 0, 1) ) ) ), "" ) -> 1 | AC20: Marshalle Julluice V. Catua | AD20: 0.499 | AE20: 36921.51 | AF20: 0.68 | AG20: Greentech Total Environmental Solutions Incorporated | AH20: Compliant | AI20: YES | AJ20: YES | AK20: YES | AL20: YES | AM20: YES | AN20: YES | AR20: 22614.77 | AS20: 0.6125 | AT20: 2491.86 | AU20: 0.0675 | AX20: 10974.55 | AY20: 0.2972 | AZ20: 840.33 | BA20: 0.0228 | BB20: =SUM(AS20,AU20,AW20) -> 0.68 | BC20: =SUM(AS20,AU20,AW20) -> 0.68 | BD20: https://embco-my.sharepoint.com/:w:/g/personal/eswmr3_emb_gov_ph/IQAACyXLumaqTYjQ7zLIUiv6AZWa4r6suKpCoYEUceqSB7U?e=QgYsgA
A21: Aurora | B21: Casiguran | C21: =CONCATENATE(A21,","," ",B21) -> Aurora, Casiguran | D21: OUTSIDE MBA | E21: Lone | F21: 16.277169 | G21: 122.12314 | H21: =CONCATENATE(F21,",",G21) -> 16.277169,122.123139 | I21: Municipal / City Plan | J21: 1289 | K21: 2017 - 2027 | L21: 2019 | M21: 2027 | O21: Queenyvel Laguisma | Q21: Diozelle L. Cabalar | R21: 3.March | Y21: =IFERROR( IF( OR(ISBLANK(T21), ISBLANK(U21)), "", MAX( 1, IF( NETWORKDAYS(T21, U21, Holiday_Dates) <= 0, 1, NETWORKDAYS(T21, U21, Holiday_Dates) - IF(T21 = U21, 0, 1) ) ) ), "" ) | Z21: =IF( OR(ISBLANK(U21), ISBLANK(V21)), "", MAX( 1, IF( NETWORKDAYS(U21, V21, Holiday_Dates) <= 0, 1, NETWORKDAYS(U21, V21, Holiday_Dates) - IF(U21 = V21, 0, 1) ) ) ) | AA21: =IFERROR( IF( OR(ISBLANK(W21), AND(ISBLANK(U21), ISBLANK(V21))), "", MAX( 1, IF( NETWORKDAYS(IF(NOT(ISBLANK(V21)), V21, U21), W21, Holiday_Dates) <= 0, 1, NETWORKDAYS(IF(NOT(ISBLANK(V21)), V21, U21), W21, Holiday_Dates) - IF(IF(NOT(ISBLANK(V21)), V21, U21) = W21, 0, 1) ) ) ), "" ) | AB21: =IFERROR( IF( OR(ISBLANK(W21), ISBLANK(X21)), "", MAX( 1, IF( NETWORKDAYS(W21, X21, Holiday_Dates) <= 0, 1, NETWORKDAYS(W21, X21, Holiday_Dates) - IF(W21 = X21, 0, 1) ) ) ), "" ) | BB21: =SUM(AS21,AU21,AW21) -> 0 | BC21: =SUM(AS21,AU21,AW21) -> 0
A22: Bataan | B22: Mariveles | C22: =CONCATENATE(A22,","," ",B22) -> Bataan, Mariveles | D22: MBA | E22: 3rd | F22: 14.435804 | G22: 120.49021 | H22: =CONCATENATE(F22,",",G22) -> 14.435804,120.490214 | I22: Municipal / City Plan | J22: 483 SERIES 2016 | K22: 2016 - 2025 | L22: 2016 | M22: 2025 | N22: For Renewal | O22: Laurence Radasa | Q22: Christle D. David | R22: 3.March | S22: R3-2026-006188 | T22: 46077 | U22: 46078 | W22: 46078 | X22: 46079 | Y22: =IFERROR( IF( OR(ISBLANK(T22), ISBLANK(U22)), "", MAX( 1, IF( NETWORKDAYS(T22, U22, Holiday_Dates) <= 0, 1, NETWORKDAYS(T22, U22, Holiday_Dates) - IF(T22 = U22, 0, 1) ) ) ), "" ) -> 1 | Z22: =IF( OR(ISBLANK(U22), ISBLANK(V22)), "", MAX( 1, IF( NETWORKDAYS(U22, V22, Holiday_Dates) <= 0, 1, NETWORKDAYS(U22, V22, Holiday_Dates) - IF(U22 = V22, 0, 1) ) ) ) | AA22: =IFERROR( IF( OR(ISBLANK(W22), AND(ISBLANK(U22), ISBLANK(V22))), "", MAX( 1, IF( NETWORKDAYS(IF(NOT(ISBLANK(V22)), V22, U22), W22, Holiday_Dates) <= 0, 1, NETWORKDAYS(IF(NOT(ISBLANK(V22)), V22, U22), W22, Holiday_Dates) - IF(IF(NOT(ISBLANK(V22)), V22, U22) = W22, 0, 1) ) ) ), "" ) -> 1 | AB22: =IFERROR( IF( OR(ISBLANK(W22), ISBLANK(X22)), "", MAX( 1, IF( NETWORKDAYS(W22, X22, Holiday_Dates) <= 0, 1, NETWORKDAYS(W22, X22, Holiday_Dates) - IF(W22 = X22, 0, 1) ) ) ), "" ) -> 1 | AC22: Marshalle Julluice V. Catua | AD22: 0.201 | AE22: 31392.2 | AF22: 0.9147 | AG22: Floridablanca Enviro Corporation | AH22: Compliant | AI22: YES | AJ22: YES | AK22: YES | AL22: YES | AM22: YES | AN22: YES | AR22: 6765.02 | AS22: 0.2155 | AT22: 4715.11 | AU22: 0.1502 | AV22: 17234.32 | AW22: 0.5409 | AX22: 1563.33 | AY22: 0.0498 | AZ22: 1114.42 | BA22: 0.0355 | BB22: =SUM(AS22,AU22,AW22) -> 0.9066 | BC22: =SUM(AS22,AU22,AW22) -> 0.9066
A23: Bulacan | B23: City Of San Jose Del Monte | C23: =CONCATENATE(A23,","," ",B23) -> Bulacan, City Of San Jose Del Monte | D23: MBA | E23: Lone | F23: 14.810227 | G23: 121.0477 | H23: =CONCATENATE(F23,",",G23) -> 14.810227,121.047703 | I23: Municipal / City Plan | J23: 197 Series of 2015 | K23: 2015 - 2024 | L23: 2015 | M23: 2024 | N23: For Renewal | O23: James Wilson T. Pena | Q23: Diozelle L. Cabalar | R23: 3.March | Y23: =IFERROR( IF( OR(ISBLANK(T23), ISBLANK(U23)), "", MAX( 1, IF( NETWORKDAYS(T23, U23, Holiday_Dates) <= 0, 1, NETWORKDAYS(T23, U23, Holiday_Dates) - IF(T23 = U23, 0, 1) ) ) ), "" ) | Z23: =IF( OR(ISBLANK(U23), ISBLANK(V23)), "", MAX( 1, IF( NETWORKDAYS(U23, V23, Holiday_Dates) <= 0, 1, NETWORKDAYS(U23, V23, Holiday_Dates) - IF(U23 = V23, 0, 1) ) ) ) | AA23: =IFERROR( IF( OR(ISBLANK(W23), AND(ISBLANK(U23), ISBLANK(V23))), "", MAX( 1, IF( NETWORKDAYS(IF(NOT(ISBLANK(V23)), V23, U23), W23, Holiday_Dates) <= 0, 1, NETWORKDAYS(IF(NOT(ISBLANK(V23)), V23, U23), W23, Holiday_Dates) - IF(IF(NOT(ISBLANK(V23)), V23, U23) = W23, 0, 1) ) ) ), "" ) | AB23: =IFERROR( IF( OR(ISBLANK(W23), ISBLANK(X23)), "", MAX( 1, IF( NETWORKDAYS(W23, X23, Holiday_Dates) <= 0, 1, NETWORKDAYS(W23, X23, Holiday_Dates) - IF(W23 = X23, 0, 1) ) ) ), "" ) | BB23: =SUM(AR23,AT23,AV23) -> 0 | BC23: =SUM(AS23,AU23,AW23) -> 0
A24: Bulacan | B24: Hagonoy | C24: =CONCATENATE(A24,","," ",B24) -> Bulacan, Hagonoy | D24: MBA | E24: 1st | F24: 14.836099 | G24: 120.7341 | H24: =CONCATENATE(F24,",",G24) -> 14.836099,120.734098 | I24: Municipal / City Plan | J24: 499A | K24: 2016 - 2025 | L24: 2018 | M24: 2025 | N24: For Renewal | O24: Ronaldo P. Roque, Jr. | Q24: Diozelle L. Cabalar | R24: 3.March | Y24: =IFERROR( IF( OR(ISBLANK(T24), ISBLANK(U24)), "", MAX( 1, IF( NETWORKDAYS(T24, U24, Holiday_Dates) <= 0, 1, NETWORKDAYS(T24, U24, Holiday_Dates) - IF(T24 = U24, 0, 1) ) ) ), "" ) | Z24: =IF( OR(ISBLANK(U24), ISBLANK(V24)), "", MAX( 1, IF( NETWORKDAYS(U24, V24, Holiday_Dates) <= 0, 1, NETWORKDAYS(U24, V24, Holiday_Dates) - IF(U24 = V24, 0, 1) ) ) ) | AA24: =IFERROR( IF( OR(ISBLANK(W24), AND(ISBLANK(U24), ISBLANK(V24))), "", MAX( 1, IF( NETWORKDAYS(IF(NOT(ISBLANK(V24)), V24, U24), W24, Holiday_Dates) <= 0, 1, NETWORKDAYS(IF(NOT(ISBLANK(V24)), V24, U24), W24, Holiday_Dates) - IF(IF(NOT(ISBLANK(V24)), V24, U24) = W24, 0, 1) ) ) ), "" ) | AB24: =IFERROR( IF( OR(ISBLANK(W24), ISBLANK(X24)), "", MAX( 1, IF( NETWORKDAYS(W24, X24, Holiday_Dates) <= 0, 1, NETWORKDAYS(W24, X24, Holiday_Dates) - IF(W24 = X24, 0, 1) ) ) ), "" ) | BB24: =SUM(AR24,AT24,AV24) -> 0 | BC24: =SUM(AS24,AU24,AW24) -> 0
A25: Nueva Ecija | B25: Jaen | C25: =CONCATENATE(A25,","," ",B25) -> Nueva Ecija, Jaen | D25: MBA | E25: 4th | F25: 15.33763 | G25: 120.90542 | H25: =CONCATENATE(F25,",",G25) -> 15.33763,120.905423 | I25: Municipal / City Plan | J25: 760 Series of 2016 | K25: 2016 - 2025 | L25: 2016 | M25: 2025 | N25: For Renewal | O25: Christine Ann V. Ramos | Q25: Zosimo P. Suyat | R25: 3.March | Y25: =IFERROR( IF( OR(ISBLANK(T25), ISBLANK(U25)), "", MAX( 1, IF( NETWORKDAYS(T25, U25, Holiday_Dates) <= 0, 1, NETWORKDAYS(T25, U25, Holiday_Dates) - IF(T25 = U25, 0, 1) ) ) ), "" ) | Z25: =IF( OR(ISBLANK(U25), ISBLANK(V25)), "", MAX( 1, IF( NETWORKDAYS(U25, V25, Holiday_Dates) <= 0, 1, NETWORKDAYS(U25, V25, Holiday_Dates) - IF(U25 = V25, 0, 1) ) ) ) | AA25: =IFERROR( IF( OR(ISBLANK(W25), AND(ISBLANK(U25), ISBLANK(V25))), "", MAX( 1, IF( NETWORKDAYS(IF(NOT(ISBLANK(V25)), V25, U25), W25, Holiday_Dates) <= 0, 1, NETWORKDAYS(IF(NOT(ISBLANK(V25)), V25, U25), W25, Holiday_Dates) - IF(IF(NOT(ISBLANK(V25)), V25, U25) = W25, 0, 1) ) ) ), "" ) | AB25: =IFERROR( IF( OR(ISBLANK(W25), ISBLANK(X25)), "", MAX( 1, IF( NETWORKDAYS(W25, X25, Holiday_Dates) <= 0, 1, NETWORKDAYS(W25, X25, Holiday_Dates) - IF(W25 = X25, 0, 1) ) ) ), "" ) | BB25: =SUM(AR25,AT25,AV25) -> 0 | BC25: =SUM(AS25,AU25,AW25) -> 0
A26: Nueva Ecija | B26: Laur | C26: =CONCATENATE(A26,","," ",B26) -> Nueva Ecija, Laur | D26: MBA | E26: 3rd | F26: 15.571914 | G26: 121.16846 | H26: =CONCATENATE(F26,",",G26) -> 15.571914,121.168456 | I26: Municipal / City Plan | J26: 195 | K26: 2016 - 2025 | L26: 2015 | M26: 2025 | N26: For Renewal | O26: Christian Jem L. Buluran | Q26: Zosimo P. Suyat | R26: 3.March | Y26: =IFERROR( IF( OR(ISBLANK(T26), ISBLANK(U26)), "", MAX( 1, IF( NETWORKDAYS(T26, U26, Holiday_Dates) <= 0, 1, NETWORKDAYS(T26, U26, Holiday_Dates) - IF(T26 = U26, 0, 1) ) ) ), "" ) | Z26: =IF( OR(ISBLANK(U26), ISBLANK(V26)), "", MAX( 1, IF( NETWORKDAYS(U26, V26, Holiday_Dates) <= 0, 1, NETWORKDAYS(U26, V26, Holiday_Dates) - IF(U26 = V26, 0, 1) ) ) ) | AA26: =IFERROR( IF( OR(ISBLANK(W26), AND(ISBLANK(U26), ISBLANK(V26))), "", MAX( 1, IF( NETWORKDAYS(IF(NOT(ISBLANK(V26)), V26, U26), W26, Holiday_Dates) <= 0, 1, NETWORKDAYS(IF(NOT(ISBLANK(V26)), V26, U26), W26, Holiday_Dates) - IF(IF(NOT(ISBLANK(V26)), V26, U26) = W26, 0, 1) ) ) ), "" ) | AB26: =IFERROR( IF( OR(ISBLANK(W26), ISBLANK(X26)), "", MAX( 1, IF( NETWORKDAYS(W26, X26, Holiday_Dates) <= 0, 1, NETWORKDAYS(W26, X26, Holiday_Dates) - IF(W26 = X26, 0, 1) ) ) ), "" ) | BB26: =SUM(AR26,AT26,AV26) -> 0 | BC26: =SUM(AS26,AU26,AW26) -> 0
A27: Nueva Ecija | B27: Peñaranda | C27: =CONCATENATE(A27,","," ",B27) -> Nueva Ecija, Peñaranda | D27: MBA | E27: 4th | F27: 15.36518 | G27: 121.01418 | H27: =CONCATENATE(F27,",",G27) -> 15.36518,121.014179 | I27: Municipal / City Plan | J27: 1357, Series of 2019 | K27: 2017 - 2027 | L27: 2019 | M27: 2027 | O27: Christine Ann V. Ramos | Q27: Zosimo P. Suyat | R27: 3.March | S27: R3-2026-007119 | Y27: =IFERROR( IF( OR(ISBLANK(T27), ISBLANK(U27)), "", MAX( 1, IF( NETWORKDAYS(T27, U27, Holiday_Dates) <= 0, 1, NETWORKDAYS(T27, U27, Holiday_Dates) - IF(T27 = U27, 0, 1) ) ) ), "" ) | Z27: =IF( OR(ISBLANK(U27), ISBLANK(V27)), "", MAX( 1, IF( NETWORKDAYS(U27, V27, Holiday_Dates) <= 0, 1, NETWORKDAYS(U27, V27, Holiday_Dates) - IF(U27 = V27, 0, 1) ) ) ) | AA27: =IFERROR( IF( OR(ISBLANK(W27), AND(ISBLANK(U27), ISBLANK(V27))), "", MAX( 1, IF( NETWORKDAYS(IF(NOT(ISBLANK(V27)), V27, U27), W27, Holiday_Dates) <= 0, 1, NETWORKDAYS(IF(NOT(ISBLANK(V27)), V27, U27), W27, Holiday_Dates) - IF(IF(NOT(ISBLANK(V27)), V27, U27) = W27, 0, 1) ) ) ), "" ) | AB27: =IFERROR( IF( OR(ISBLANK(W27), ISBLANK(X27)), "", MAX( 1, IF( NETWORKDAYS(W27, X27, Holiday_Dates) <= 0, 1, NETWORKDAYS(W27, X27, Holiday_Dates) - IF(W27 = X27, 0, 1) ) ) ), "" ) | BB27: =SUM(AR27,AT27,AV27) -> 0 | BC27: =SUM(AS27,AU27,AW27) -> 0
A28: Pampanga | B28: Apalit | C28: =CONCATENATE(A28,","," ",B28) -> Pampanga, Apalit | D28: MBA | E28: 4th | F28: 14.9536 | G28: 120.7685 | H28: =CONCATENATE(F28,",",G28) -> 14.9536,120.7685 | I28: Municipal / City Plan | J28: 1241 | K28: 2017 - 2027 | L28: 2019 | M28: 2027 | O28: Glaiza S.Gaza | Q28: Sherwin John Y. Loquellano | R28: 3.March | Y28: =IFERROR( IF( OR(ISBLANK(T28), ISBLANK(U28)), "", MAX( 1, IF( NETWORKDAYS(T28, U28, Holiday_Dates) <= 0, 1, NETWORKDAYS(T28, U28, Holiday_Dates) - IF(T28 = U28, 0, 1) ) ) ), "" ) | Z28: =IF( OR(ISBLANK(U28), ISBLANK(V28)), "", MAX( 1, IF( NETWORKDAYS(U28, V28, Holiday_Dates) <= 0, 1, NETWORKDAYS(U28, V28, Holiday_Dates) - IF(U28 = V28, 0, 1) ) ) ) | AA28: =IFERROR( IF( OR(ISBLANK(W28), AND(ISBLANK(U28), ISBLANK(V28))), "", MAX( 1, IF( NETWORKDAYS(IF(NOT(ISBLANK(V28)), V28, U28), W28, Holiday_Dates) <= 0, 1, NETWORKDAYS(IF(NOT(ISBLANK(V28)), V28, U28), W28, Holiday_Dates) - IF(IF(NOT(ISBLANK(V28)), V28, U28) = W28, 0, 1) ) ) ), "" ) | AB28: =IFERROR( IF( OR(ISBLANK(W28), ISBLANK(X28)), "", MAX( 1, IF( NETWORKDAYS(W28, X28, Holiday_Dates) <= 0, 1, NETWORKDAYS(W28, X28, Holiday_Dates) - IF(W28 = X28, 0, 1) ) ) ), "" ) | BB28: =SUM(AR28,AT28,AV28) -> 0 | BC28: =SUM(AS28,AU28,AW28) -> 0
A29: Pampanga | B29: Candaba | C29: =CONCATENATE(A29,","," ",B29) -> Pampanga, Candaba | D29: MBA | E29: 4th | F29: 15.092935 | G29: 120.82806 | H29: =CONCATENATE(F29,",",G29) -> 15.092935,120.828063 | I29: Municipal / City Plan | J29: 240 series of 2015 | K29: 2015 - 2024 | L29: 2015 | M29: 2024 | N29: For Renewal | O29: Roger T. Encarnacion II | Q29: Jun D. Guillermo | R29: 3.March | Y29: =IFERROR( IF( OR(ISBLANK(T29), ISBLANK(U29)), "", MAX( 1, IF( NETWORKDAYS(T29, U29, Holiday_Dates) <= 0, 1, NETWORKDAYS(T29, U29, Holiday_Dates) - IF(T29 = U29, 0, 1) ) ) ), "" ) | Z29: =IF( OR(ISBLANK(U29), ISBLANK(V29)), "", MAX( 1, IF( NETWORKDAYS(U29, V29, Holiday_Dates) <= 0, 1, NETWORKDAYS(U29, V29, Holiday_Dates) - IF(U29 = V29, 0, 1) ) ) ) | AA29: =IFERROR( IF( OR(ISBLANK(W29), AND(ISBLANK(U29), ISBLANK(V29))), "", MAX( 1, IF( NETWORKDAYS(IF(NOT(ISBLANK(V29)), V29, U29), W29, Holiday_Dates) <= 0, 1, NETWORKDAYS(IF(NOT(ISBLANK(V29)), V29, U29), W29, Holiday_Dates) - IF(IF(NOT(ISBLANK(V29)), V29, U29) = W29, 0, 1) ) ) ), "" ) | AB29: =IFERROR( IF( OR(ISBLANK(W29), ISBLANK(X29)), "", MAX( 1, IF( NETWORKDAYS(W29, X29, Holiday_Dates) <= 0, 1, NETWORKDAYS(W29, X29, Holiday_Dates) - IF(W29 = X29, 0, 1) ) ) ), "" ) | BB29: =SUM(AR29,AT29,AV29) -> 0 | BC29: =SUM(AS29,AU29,AW29) -> 0
A30: Pampanga | B30: Guagua | C30: =CONCATENATE(A30,","," ",B30) -> Pampanga, Guagua | D30: MBA | E30: 2nd | F30: 14.965207 | G30: 120.63334 | H30: =CONCATENATE(F30,",",G30) -> 14.965207,120.633338 | I30: Municipal / City Plan | J30: 158 | K30: 2015 - 2024 | L30: 2015 | M30: 2024 | N30: For Renewal | O30: Sebastian Josh V. Manalang | Q30: Jun D. Guillermo | R30: 3.March | Y30: =IFERROR( IF( OR(ISBLANK(T30), ISBLANK(U30)), "", MAX( 1, IF( NETWORKDAYS(T30, U30, Holiday_Dates) <= 0, 1, NETWORKDAYS(T30, U30, Holiday_Dates) - IF(T30 = U30, 0, 1) ) ) ), "" ) | Z30: =IF( OR(ISBLANK(U30), ISBLANK(V30)), "", MAX( 1, IF( NETWORKDAYS(U30, V30, Holiday_Dates) <= 0, 1, NETWORKDAYS(U30, V30, Holiday_Dates) - IF(U30 = V30, 0, 1) ) ) ) | AA30: =IFERROR( IF( OR(ISBLANK(W30), AND(ISBLANK(U30), ISBLANK(V30))), "", MAX( 1, IF( NETWORKDAYS(IF(NOT(ISBLANK(V30)), V30, U30), W30, Holiday_Dates) <= 0, 1, NETWORKDAYS(IF(NOT(ISBLANK(V30)), V30, U30), W30, Holiday_Dates) - IF(IF(NOT(ISBLANK(V30)), V30, U30) = W30, 0, 1) ) ) ), "" ) | AB30: =IFERROR( IF( OR(ISBLANK(W30), ISBLANK(X30)), "", MAX( 1, IF( NETWORKDAYS(W30, X30, Holiday_Dates) <= 0, 1, NETWORKDAYS(W30, X30, Holiday_Dates) - IF(W30 = X30, 0, 1) ) ) ), "" ) | BB30: =SUM(AR30,AT30,AV30) -> 0 | BC30: =SUM(AS30,AU30,AW30) -> 0
A31: Zambales | B31: San Marcelino | C31: =CONCATENATE(A31,","," ",B31) -> Zambales, San Marcelino | D31: OUTSIDE MBA | E31: 1st | F31: 14.974092 | G31: 120.15555 | H31: =CONCATENATE(F31,",",G31) -> 14.974092,120.155547 | I31: Municipal / City Plan | J31: 1253 | K31: 2017 - 2027 | L31: 2019 | M31: 2027 | O31: Ryan Ace R. Angel | Q31: Jun D. Guillermo | R31: 3.March | S31: R3-2026-008553 | T31: 46085 | U31: 46094 | W31: 46097 | Y31: =IFERROR( IF( OR(ISBLANK(T31), ISBLANK(U31)), "", MAX( 1, IF( NETWORKDAYS(T31, U31, Holiday_Dates) <= 0, 1, NETWORKDAYS(T31, U31, Holiday_Dates) - IF(T31 = U31, 0, 1) ) ) ), "" ) -> 7 | Z31: =IF( OR(ISBLANK(U31), ISBLANK(V31)), "", MAX( 1, IF( NETWORKDAYS(U31, V31, Holiday_Dates) <= 0, 1, NETWORKDAYS(U31, V31, Holiday_Dates) - IF(U31 = V31, 0, 1) ) ) ) | AA31: =IFERROR( IF( OR(ISBLANK(W31), AND(ISBLANK(U31), ISBLANK(V31))), "", MAX( 1, IF( NETWORKDAYS(IF(NOT(ISBLANK(V31)), V31, U31), W31, Holiday_Dates) <= 0, 1, NETWORKDAYS(IF(NOT(ISBLANK(V31)), V31, U31), W31, Holiday_Dates) - IF(IF(NOT(ISBLANK(V31)), V31, U31) = W31, 0, 1) ) ) ), "" ) -> 1 | AB31: =IFERROR( IF( OR(ISBLANK(W31), ISBLANK(X31)), "", MAX( 1, IF( NETWORKDAYS(W31, X31, Holiday_Dates) <= 0, 1, NETWORKDAYS(W31, X31, Holiday_Dates) - IF(W31 = X31, 0, 1) ) ) ), "" ) | BB31: =SUM(AR31,AT31,AV31) -> 0 | BC31: =SUM(AS31,AU31,AW31) -> 0
A32: Tarlac | B32: San Manuel | C32: =CONCATENATE(A32,","," ",B32) -> Tarlac, San Manuel | D32: OUTSIDE MBA | E32: 1st | F32: 15.799371 | G32: 120.60732 | H32: =CONCATENATE(F32,",",G32) -> 15.7993705,120.6073187 | I32: Municipal / City Plan | J32: Resolution No. 1604, Series of 2023 | K32: 2022 - 2031 | L32: 2023 | M32: 2031 | O32: Jasper Kieht B. Pili | Q32: Jan Emerson C. Gonzales | R32: 3.March | Y32: =IFERROR( IF( OR(ISBLANK(T32), ISBLANK(U32)), "", MAX( 1, IF( NETWORKDAYS(T32, U32, Holiday_Dates) <= 0, 1, NETWORKDAYS(T32, U32, Holiday_Dates) - IF(T32 = U32, 0, 1) ) ) ), "" ) | Z32: =IF( OR(ISBLANK(U32), ISBLANK(V32)), "", MAX( 1, IF( NETWORKDAYS(U32, V32, Holiday_Dates) <= 0, 1, NETWORKDAYS(U32, V32, Holiday_Dates) - IF(U32 = V32, 0, 1) ) ) ) | AA32: =IFERROR( IF( OR(ISBLANK(W32), AND(ISBLANK(U32), ISBLANK(V32))), "", MAX( 1, IF( NETWORKDAYS(IF(NOT(ISBLANK(V32)), V32, U32), W32, Holiday_Dates) <= 0, 1, NETWORKDAYS(IF(NOT(ISBLANK(V32)), V32, U32), W32, Holiday_Dates) - IF(IF(NOT(ISBLANK(V32)), V32, U32) = W32, 0, 1) ) ) ), "" ) | AB32: =IFERROR( IF( OR(ISBLANK(W32), ISBLANK(X32)), "", MAX( 1, IF( NETWORKDAYS(W32, X32, Holiday_Dates) <= 0, 1, NETWORKDAYS(W32, X32, Holiday_Dates) - IF(W32 = X32, 0, 1) ) ) ), "" ) | BB32: =SUM(AR32,AT32,AV32) -> 0 | BC32: =SUM(AS32,AU32,AW32) -> 0
