Workbook

Sheet ENMO TARGET
A1: No. | B1: PROVINCE | C1: ENMO | D1: 10 Year Plan | E1: MRF | F1: Equipment | G1: ODS | H1: SLF | I1: Transfer Station | J1: RCA | K1: Trash Trap | L1: Preliminary Disinpection Facility
A2: 1 | B2: AURORA | C2: Zaila Mae R. Leander | D2: 4 | E2: 12 | F2: 3 | G2: 1 | H2: 1 | J2: 2 | L2: 1
A3: 2 | B3: AURORA | C3: Nikko Jay M. Valenzuela | D3: 2 | E3: 4 | F3: 2 | H3: 2 | L3: 1
A4: 3 | B4: AURORA | C4: Queenyvel R. Laguisma | D4: 3 | E4: 3 | F4: 3 | J4: 3 | L4: 1
A5: 4 | B5: BATAAN | C5: Dennis G. Tolentino | D5: 6 | E5: 10 | F5: 6 | G5: 2 | H5: 3 | L5: 1
A6: 5 | B6: BATAAN | C6: John-lester C. Signio | D6: 4 | E6: 4 | F6: 4 | G6: 3 | L6: 1
A7: 6 | B7: BATAAN | C7: Laurence Radasa | D7: 3 | E7: 12 | F7: 3 | G7: 2 | I7: 1 | J7: 2
A8: 7 | B8: BULACAN | C8: Jasmine Marie J. Nicolas | D8: 5 | E8: 7 | F8: 6 | I8: 3 | K8: 21
A9: 8 | B9: BULACAN | C9: Ronaldo P. Roque Jr. | D9: 5 | E9: 5 | F9: 5 | G9: 2 | I9: 2 | K9: 8
A10: 9 | B10: BULACAN | C10: Vacant
A11: 10 | B11: BULACAN | C11: James Wilson T. Peña | D11: 6 | E11: 8 | F11: 6 | G11: 2 | K11: 7 | L11: 2
A12: 11 | B12: NUEVA ECIJA | C12: Hosannah R. Sabio | D12: 6 | E12: 6 | F12: 7 | G12: 4 | I12: 6 | L12: 2
A13: 12 | B13: NUEVA ECIJA | C13: Gem C. Vicencio | D13: 6 | E13: 6 | F13: 6 | G13: 5 | I13: 6
A14: 13 | B14: NUEVA ECIJA | C14: Jan Emerson C. Gonzales | D14: 7 | E14: 9 | F14: 7 | H14: 2 | I14: 4 | J14: 1
A15: 14 | B15: NUEVA ECIJA | C15: Aser A. Inocencio, Jr. | D15: 7 | E15: 10 | F15: 8 | G15: 1 | H15: 1 | I15: 3 | J15: 3 | L15: 1
A16: 15 | B16: NUEVA ECIJA | C16: Christine Ann V. Ramos | D16: 6 | E16: 7 | F16: 7 | G16: 4 | I16: 6 | K16: 11 | L16: 1
A17: 16 | B17: PAMPANGA | C17: Roger T. Encarnacion II | D17: 6 | E17: 7 | F17: 6 | G17: 6 | K17: 8
A18: 17 | B18: PAMPANGA | C18: Elyza A. Evilla | D18: 5 | E18: 6 | F18: 5 | H18: 3 | I18: 2 | K18: 31 | L18: 4
A19: 18 | B19: PAMPANGA | C19: Glaiza S.Gaza | D19: 5 | E19: 6 | F19: 5 | G19: 4 | I19: 2 | K19: 14
A20: 19 | B20: PAMPANGA | C20: Ivy M. Castro | D20: 5 | E20: 4 | F20: 5 | G20: 2 | I20: 2 | K20: 13
A21: 20 | B21: TARLAC | C21: Joshua A. Capones | D21: 7 | E21: 6 | F21: 6 | G21: 1 | I21: 1 | L21: 2
A22: 21 | B22: TARLAC | C22: Jasper Kieht B. Pili | D22: 6 | E22: 5 | F22: 6 | G22: 1
A23: 22 | B23: TARLAC | C23: Gretzhen M. Apolonio | D23: 6 | E23: 7 | F23: 7 | H23: 1
A24: 23 | B24: ZAMBALES | C24: Larizze A. Santos | D24: 5 | E24: 5 | F24: 5 | G24: 2 | H24: 1 | I24: 2 | J24: 2 | L24: 2
A25: 24 | B25: ZAMBALES | C25: Vacant
A26: 25 | B26: ZAMBALES | C26: Ryan Ace R. Angel | D26: 3 | E26: 12 | F26: 3 | G26: 1 | H26: 2

Sheet Data Validation
A1: Type of Plan | C1: SLF | H1: MRF | K1: EQUIPEMENT | M1: ODS | Q1: PDS | T1: TRASH TRAP | W1: TRANSFER STATION | AD1: RCA
A2: Municipal / City Plan | B2: YES | H2: OPERATIONAL | K2: OPERATIONAL | M2: FULLY REHABILITATED | N2: COMPLIANT | Q2: OPERATIONAL | T2: OPERATIONAL | W2: OPERATIONAL | X2: FACILITY | Y2: LGU | AD2: OPERATIONAL | AE2: FACILITY
A3: Provincial Plan | B3: NO | H3: NON-OPERATIONAL | K3: NON-OPERATIONAL | M3: PARTIAL REHABILITATED | N3: NOT COMPLIANT | Q3: NON-OPERATIONAL | T3: NON-OPERATIONAL | W3: NON-OPERATIONAL | X3: BIN | Y3: PRIVATE OWNERSHIP | AD3: NON-OPERATIONAL | AE3: BIN
H4: UNDER CONSTRUCTION | K4: PLANNING TO TRANSFER | M4: NOT YET REHABILITATED | Q4: PLANNING TO TRANSFER | W4: UNDER CONSTRUCTION | AD4: UNDER CONSTRUCTION
B5: YES | H5: OPERATING AS OPEN DUMPSITE | K5: PLANNING TO RETURN | M5: OPERATING AS OPEN DUMPSITE | Q5: OTHER | W5: OPERATING AS OPEN DUMPSITE | AD5: OPERATING AS OPEN DUMPSITE
B6: NO
A7: Type of MRF | B7: N/A
A8: EMB FUNDED MRF
A9: EMB FUNDED BRGY MRF
A10: LGU FUNDED MRF
A13: 1.January
A14: 2.February
A15: 3.March
A16: 4.April
A17: 5.May
A18: 6.June
A19: 7.July
A20: 8.August
A21: 9.September
... A24: 12.December

Sheet Sheet2
A1: Province | B1: Nueva_Ecija
A3: Count of Accomplishment for the month of | B3: Accomplishment for the month of
A4: Municipality | B4: July | C4: August | D4: September | E4: October | F4: November | G4: Grand Total
A5: Aliaga | C5: 2 | D5: 2 | E5: 3 | G5: 7
A6: Bongabon | D6: 2 | G6: 2
A7: Cabanatuan City | C7: 4 | D7: 2 | E7: 3 | F7: 3 | G7: 12
A8: Cabiao | C8: 1 | D8: 2 | E8: 1 | G8: 4
A9: Carranglan | E9: 3 | G9: 3
A10: City of Gapan | D10: 4 | F10: 2 | G10: 6
A11: City of Palayan (Capital) | C11: 5 | E11: 3 | G11: 8
A12: Cuyapo | E12: 3 | G12: 3
A13: Guimba | C13: 4 | D13: 1 | G13: 5
A14: Jaen | B14: 1 | C14: 2 | D14: 1 | E14: 4 | G14: 8
A15: Laur | D15: 1 | G15: 1
A16: Licab | C16: 1 | G16: 1
A17: Llanera | C17: 1 | D17: 1 | E17: 3 | G17: 5
A18: Lupao | B18: 1 | D18: 2 | G18: 3
A19: Penaranda | E19: 3 | G19: 3
A20: Quezon | B20: 1 | D20: 1 | E20: 2 | F20: 3 | G20: 7
A21: Rizal | D21: 5 | G21: 5
A22: San Antonio | C22: 3 | F22: 3 | G22: 6
A23: San Jose City | C23: 3 | D23: 2 | F23: 2 | G23: 7
A24: San Leonardo | E24: 1 | G24: 1
A25: Santa Rosa | B25: 1 | C25: 2 | D25: 3 | E25: 1 | G25: 7
A26: Santo Domingo | B26: 3 | G26: 3
A27: Science City of Munoz | B27: 6 | C27: 1 | G27: 7
A28: Talavera | B28: 1 | C28: 2 | E28: 1 | G28: 4
A29: Grand Total | B29: 14 | C29: 31 | D29: 29 | E29: 31 | F29: 13 | G29: 118

Sheet Sheet3
A3: Province | B3: Count of Manila Bay Area (MBA)
A4: Aurora | B4: 19
A5: Bataan | B5: 22
A6: Bataan | B6: 4
A7: Bulacan | B7: 44
A8: Nueva Ecija | B8: 38
A9: Pampanga | B9: 24
A10: Tarlac | B10: 20
A11: Zambales | B11: 23
A12: Grand Total | B12: 194

Sheet 10-YEAR SWM PLAN
A1: Province | B1: Municipality | C1: CONCATENATE | D1: Manila Bay Area (MBA) | E1: Congressional District | F1: Long. | G1: Lat. | H1: Location | I1: Type of SWM Plan | J1: Resolution No. | K1: Period Covered | L1: Year Approved | M1: End Period | N1: For Renewal | O1: Target Month | P1: ENMO Assigned | Q1: ESWM Staff | R1: Focal Person | S1: IIS NUMBER | T1: Date of Monitoring | U1: Date Report Prepared (Submitted to IIS by ENMO) | V1: Date Report Reviewed (by ESWM Staff) | W1: Date Report Reviewed (by Focal Person) | X1: Date Report Approved | Y1: Total No. of Days (Report prepared) | Z1: Total No. of Days (Report Reviewed by ESWM Staff) | AA1: Total No. of Days (Report Reviewed by Focal) | AB1: Total No. of Days (Report Approved by C, ESWM) | AC1: Tracking of Reports (To be filled out by Planning Section) | AD1: PCG | AE1: Total Waste Generation | AF1: Waste Diversion Rate (%) | AG1: LGU Final Disposal | AH1: Remarks and Recommendation (Compliant/ Non-Compliant) | AI1: a. source reduction activities at source are present | AJ1: b. Collection segregated collection | AK1: c. Storage and setout (Segregation at source) | AL1: d. Processing MRF | AM1: e. Transfer Station | AN1: f. Disposal Facilities | AO1: Advise Letter/Notice Date Issued | AP1: Compliance to Advise/ Letter Issued | AQ1: Remarks | AR1: Total Waste Generation | AS1: Per Capita Per Day | AT1: Biodegradable Wastes (kg/day) | AU1: Bio (%) | AV1: Recyclable Wastes (kg/day) | AW1: Recyclable (%) | AX1: Residual with potential (kg/day) | AY1: Residual with Potential (%) | AZ1: Residual Wastes for Disposal (kg/day) | BA1: Residual (%) | BB1: Special Wastes (kg/day) | BC1: Special (%) | BD1: Total Waste Generation | BE1: Per Capita Per Day | BF1: Biodegradable Wastes (kg/day) | BG1: Bio (%) | BH1: Recyclable Wastes (kg/day) | BI1: Recyclable (%) | BJ1: Residual with potential (kg/day) | BK1: Residual with Potential (%) | BL1: Residual Wastes for Disposal (kg/day) | BM1: Residual (%) | BN1: Special Wastes (kg/day) | BO1: Special (%) | BP1: Waste Diversion Rate (%) | BQ1: Disposal Rate (%)
A2: PAMPANGA | B2: BACOLOR | C2: PAMPANGA, BACOLOR | D2: MBA | E2: 3rd | F2: 14.9966 | G2: 120.6517 | H2: =CONCATENATE(F2,",",G2) -> 14.9966,120.6517 | I2: Municipal / City Plan | J2: NSWMC Resolution No. 1638, Series of 2023 | K2: 2022 - 2031 | L2: 2022 | M2: 2031 | O2: 1.January | P2: Ivy M. Castro | Q2: Maria Cecilia Pascual | R2: Yves Yshmael M. Balagtas | S2: R3-2025-001650 | T2: 45673 | U2: 45677 | W2: 45681 | X2: 45681 | Y2: =IF( OR(ISBLANK(T2), ISBLANK(U2)), "", MAX(1, IF( NETWORKDAYS(T2, U2) <= 0, 1, NETWORKDAYS(T2, U2) - IF(T2 = U2, 0, 1) )) ) -> 2 | Z2: =IF( OR(ISBLANK(U2), ISBLANK(V2)), "", MAX(1, IF( NETWORKDAYS(U2, V2) <= 0, 1, NETWORKDAYS(U2, V2) - IF(U2 = V2, 0, 1) )) ) | AA2: =IF( OR(IF(V2<>"", V2, U2)="", W2=""), "", MAX(1, IF( NETWORKDAYS(IF(V2<>"", V2, U2), W2) <= 0, 1, NETWORKDAYS(IF(V2<>"", V2, U2), W2) - IF(IF(V2<>"", V2, U2)=W2, 0, 1) ) ) ) -> 4 | AB2: =IF( OR(ISBLANK(W2), ISBLANK(X2)), "", MAX(1, IF( NETWORKDAYS(W2, X2) <= 0, 1, NETWORKDAYS(W2, X2) - IF(W2 = X2, 0, 1) )) ) -> 1 | AC2: Received by Planning | AD2: 236 | AE2: 18436.48 | AH2: Compliant | AI2: YES | AJ2: YES | AK2: YES | AL2: YES | AM2: YES | AN2: YES | AR2: 25115.75 | AT2: 9280.27 | AV2: 8469.03 | AX2: 1444.16 | AZ2: 2732.59 | BB2: 3189.7 | BD2: =SUM(BF2,BH2,BJ2,BL2,BN2) -> 0 | BP2: =SUM(BF2,BH2,BJ2)/BD2*100 -> #DIV/0! | BQ2: =SUM(BL2,BN2)/BD2*100 -> #DIV/0!
A3: PAMPANGA | B3: CITY OF SAN FERNANDO | C3: PAMPANGA, CITY OF SAN FERNANDO | D3: MBA | E3: 3rd | F3: 15.0279 | G3: 120.6937 | H3: =CONCATENATE(F3,",",G3) -> 15.0279,120.6937 | I3: Municipal / City Plan | J3: 167 series 2015 | K3: 2015 - 2024 | L3: 2015 | M3: 2024 | N3: For Renewal | O3: 1.January | P3: Elyza A. Evilla | Q3: Maria Cecilia Pascual | R3: Yves Yshmael M. Balagtas | S3: R3-2025-002191 | T3: 45678 | U3: 45680 | W3: 45681 | X3: 45681 | Y3: =IF( OR(ISBLANK(T3), ISBLANK(U3)), "", MAX(1, IF( NETWORKDAYS(T3, U3) <= 0, 1, NETWORKDAYS(T3, U3) - IF(T3 = U3, 0, 1) )) ) -> 2 | Z3: =IF( OR(ISBLANK(U3), ISBLANK(V3)), "", MAX(1, IF( NETWORKDAYS(U3, V3) <= 0, 1, NETWORKDAYS(U3, V3) - IF(U3 = V3, 0, 1) )) ) | AA3: =IF( OR(IF(V3<>"", V3, U3)="", W3=""), "", MAX(1, IF( NETWORKDAYS(IF(V3<>"", V3, U3), W3) <= 0, 1, NETWORKDAYS(IF(V3<>"", V3, U3), W3) - IF(IF(V3<>"", V3, U3)=W3, 0, 1) ) ) ) -> 1 | AB3: =IF( OR(ISBLANK(W3), ISBLANK(X3)), "", MAX(1, IF( NETWORKDAYS(W3, X3) <= 0, 1, NETWORKDAYS(W3, X3) - IF(W3 = X3, 0, 1) )) ) -> 1 | AC3: Received by Planning | AD3: 0.72 | AE3: 214860.78 | AH3: Compliant | AI3: YES | AJ3: YES | AK3: YES | AL3: YES | AM3: YES | AN3: YES | AR3: 327929.32 | AT3: 196331.28 | AV3: 64208.56 | AX3: 27546.06 | AZ3: 32497.8 | BB3: 7345.62 | BD3: =SUM(BF3,BH3,BJ3,BL3,BN3) -> 0 | BP3: =SUM(BF3,BH3,BJ3)/BD3*100 -> #DIV/0! | BQ3: =SUM(BL3,BN3)/BD3*100 -> #DIV/0!
A4: ZAMBALES | B4: OLONGAPO CITY | C4: ZAMBALES, OLONGAPO CITY | D4: OUTSIDE MBA | E4: 1st | F4: 14.842411 | G4: 120.28765 | H4: =CONCATENATE(F4,",",G4) -> 14.842411,120.287647 | I4: Municipal / City Plan | J4: NSWMC Resolution No. 1639, Series of 2023 | K4: 2023 - 2032 | L4: 2023 | M4: 2032 | O4: 1.January | P4: Larizze A. Santos | Q4: Ryan Christian R. Nunag | R4: Jun D. Guillermo | S4: R3-2025-001966 | T4: 45673 | U4: 45679 | V4: 45679 | W4: 45680 | X4: 45680 | Y4: =IF( OR(ISBLANK(T4), ISBLANK(U4)), "", MAX(1, IF( NETWORKDAYS(T4, U4) <= 0, 1, NETWORKDAYS(T4, U4) - IF(T4 = U4, 0, 1) )) ) -> 4 | Z4: =IF( OR(ISBLANK(U4), ISBLANK(V4)), "", MAX(1, IF( NETWORKDAYS(U4, V4) <= 0, 1, NETWORKDAYS(U4, V4) - IF(U4 = V4, 0, 1) )) ) -> 1 | AA4: =IF( OR(ISBLANK(U4), ISBLANK(W4)), "", MAX(1, IF( NETWORKDAYS(U4, W4) <= 0, 1, NETWORKDAYS(U4, W4) - IF(U4 = W4, 0, 1) )) ) -> 1 | AB4: =IF( OR(ISBLANK(W4), ISBLANK(X4)), "", MAX(1, IF( NETWORKDAYS(W4, X4) <= 0, 1, NETWORKDAYS(W4, X4) - IF(W4 = X4, 0, 1) )) ) -> 1 | AC4: Received by Planning | AD4: 0.893 | AE4: 252160.88 | AF4: 0.7684 | AG4: LGU SLF | AH4: Compliant | AI4: YES | AJ4: YES | AK4: YES | AL4: YES | AN4: YES | AR4: 303429.12 | AT4: 123738.39 | AV4: 94548.51 | AX4: 14868.03 | AZ4: 60685.82 | BB4: 9588.36 | BD4: =SUM(BF4,BH4,BJ4,BL4,BN4) -> 0 | BP4: =SUM(BF4,BH4,BJ4)/BD4*100 -> #DIV/0! | BQ4: =SUM(BL4,BN4)/BD4*100 -> #DIV/0!
A5: AURORA | B5: PROVINCIAL GOVERNMENT OF AURORA | C5: AURORA, PROVINCIAL GOVERNMENT OF AURORA | D5: OUTSIDE MBA | F5: 15.755878 | G5: 121.55054 | H5: =CONCATENATE(F5,",",G5) -> 15.755878,121.550537 | I5: Provincial Plan | J5: NSWMC RESO NO. 855A SERIES OF 2019 | K5: 2018 - 2028 | L5: 2019 | M5: s | O5: 10.October | P5: Zaila Mae Leander | R5: Ryan Christian R. Nunag | S5: R3-2025-033200 | T5: 45930 | U5: 45932 | W5: 45938 | X5: 45940 | Y5: =IF( OR(ISBLANK(T5), ISBLANK(U5)), "", MAX(1, IF( NETWORKDAYS(T5, U5) <= 0, 1, NETWORKDAYS(T5, U5) - IF(T5 = U5, 0, 1) )) ) -> 2 | Z5: =IF( OR(ISBLANK(U5), ISBLANK(V5)), "", MAX(1, IF( NETWORKDAYS(U5, V5) <= 0, 1, NETWORKDAYS(U5, V5) - IF(U5 = V5, 0, 1) )) ) | AA5: =IF( OR(IF(V5<>"", V5, U5)="", W5=""), "", MAX(1, IF( NETWORKDAYS(IF(V5<>"", V5, U5), W5) <= 0, 1, NETWORKDAYS(IF(V5<>"", V5, U5), W5) - IF(IF(V5<>"", V5, U5)=W5, 0, 1) ) ) ) -> 4 | AB5: =IF( OR(ISBLANK(W5), ISBLANK(X5)), "", MAX(1, IF( NETWORKDAYS(W5, X5) <= 0, 1, NETWORKDAYS(W5, X5) - IF(W5 = X5, 0, 1) )) ) -> 2 | AC5: Received by Planning | AD5: 0.36 | AE5: 37538.47 | AF5: 86.22 | AG5: LGU owned SLF (Ma. Aurora, Dingalan and Dipaculao) | AH5: Compliant | AI5: YES | AJ5: YES | AK5: YES | AM5: YES | AN5: YES | AR5: 37538.47 | AT5: 13920.56 | AV5: 7540.04 | AZ5: 7540.04 | BB5: 1920.8 | BD5: =SUM(BF5,BH5,BJ5,BL5,BN5) -> 0 | BP5: =SUM(BF5,BH5,BJ5)/BD5*100 -> #DIV/0! | BQ5: =SUM(BL5,BN5)/BD5*100 -> #DIV/0!
A6: BATAAN | B6: ORANI | C6: BATAAN, ORANI | D6: MBA | E6: 1st | F6: 14.802093 | G6: 120.53664 | H6: =CONCATENATE(F6,",",G6) -> 14.802093,120.536636 | I6: Municipal / City Plan | J6: 1084 series of 2018 | K6: 2017 - 2028 | L6: 2018 | M6: 2028 | O6: 10.October | P6: John-lester Signio | R6: Christle D. David | S6: R3-2025-034269 | T6: 45939 | U6: 45940 | W6: 45943 | X6: 45945 | Y6: =IF( OR(ISBLANK(T6), ISBLANK(U6)), "", MAX(1, IF( NETWORKDAYS(T6, U6) <= 0, 1, NETWORKDAYS(T6, U6) - IF(T6 = U6, 0, 1) )) ) -> 1 | Z6: =IF( OR(ISBLANK(U6), ISBLANK(V6)), "", MAX(1, IF( NETWORKDAYS(U6, V6) <= 0, 1, NETWORKDAYS(U6, V6) - IF(U6 = V6, 0, 1) )) ) | AA6: =IF( OR(IF(V6<>"", V6, U6)="", W6=""), "", MAX(1, IF( NETWORKDAYS(IF(V6<>"", V6, U6), W6) <= 0, 1, NETWORKDAYS(IF(V6<>"", V6, U6), W6) - IF(IF(V6<>"", V6, U6)=W6, 0, 1) ) ) ) -> 1 | AB6: =IF( OR(ISBLANK(W6), ISBLANK(X6)), "", MAX(1, IF( NETWORKDAYS(W6, X6) <= 0, 1, NETWORKDAYS(W6, X6) - IF(W6 = X6, 0, 1) )) ) -> 2 | AC6: Received by Planning | AD6: 0.765 | AE6: 52223.13 | AF6: 0.77 | AG6: Floridablanca Enviro Corporation | AH6: =IF(AND(AI6 = "YES", AJ6 = "YES", AK6 = "YES", AL6 = "YES", AN6 = "YES"), "Compliant", "Not Compliant") -> Compliant | AI6: YES | AJ6: YES | AK6: YES | AL6: YES | AM6: YES | AN6: YES | AR6: 20513.15 | AT6: 8342.7 | AV6: 5222.65 | AX6: 4244.17 | AZ6: 1238.99 | BB6: 1464.64 | BD6: =SUM(BF6,BH6,BJ6,BL6,BN6) -> 0 | BP6: =SUM(BF6,BH6,BJ6)/BD6*100 -> #DIV/0! | BQ6: =SUM(BL6,BN6)/BD6*100 -> #DIV/0!
A7: BATAAN | B7: ORION | C7: BATAAN, ORION | D7: MBA | E7: 2nd | F7: 14.621155 | G7: 120.57647 | H7: =CONCATENATE(F7,",",G7) -> 14.621155,120.576472 | I7: Municipal / City Plan | J7: nswmc res.974 s2017 | K7: 2015 - 2025 | L7: 2017 | M7: 2025 | N7: For Renewal | O7: 10.October | P7: Dennis Tolentino | R7: Christle D. David | S7: R3-2025-034326 | T7: 45940 | U7: 45942 | W7: 45943 | X7: 45944 | Y7: =IF( OR(ISBLANK(T7), ISBLANK(U7)), "", MAX(1, IF( NETWORKDAYS(T7, U7) <= 0, 1, NETWORKDAYS(T7, U7) - IF(T7 = U7, 0, 1) )) ) -> 1 | Z7: =IF( OR(ISBLANK(U7), ISBLANK(V7)), "", MAX(1, IF( NETWORKDAYS(U7, V7) <= 0, 1, NETWORKDAYS(U7, V7) - IF(U7 = V7, 0, 1) )) ) | AA7: =IF( OR(IF(V7<>"", V7, U7)="", W7=""), "", MAX(1, IF( NETWORKDAYS(IF(V7<>"", V7, U7), W7) <= 0, 1, NETWORKDAYS(IF(V7<>"", V7, U7), W7) - IF(IF(V7<>"", V7, U7)=W7, 0, 1) ) ) ) -> 1 | AB7: =IF( OR(ISBLANK(W7), ISBLANK(X7)), "", MAX(1, IF( NETWORKDAYS(W7, X7) <= 0, 1, NETWORKDAYS(W7, X7) - IF(W7 = X7, 0, 1) )) ) -> 1 | AC7: Received by Planning | AD7: 0.593 | AE7: 33610 | AF7: 77.57 | AG7: Pyrolysis Equipment | AH7: =IF(AND(AI7 = "YES", AJ7 = "YES", AK7 = "YES", AL7 = "YES", AN7 = "YES"), "Compliant", "Not Compliant") -> Not Compliant | AR7: 18803.44 | AT7: 7647.36 | AV7: 3634.71 | AX7: 5043.08 | AZ7: 1135.73 | BB7: 1342.57 | BD7: =SUM(BF7,BH7,BJ7,BL7,BN7) -> 0 | BP7: =SUM(BF7,BH7,BJ7)/BD7*100 -> #DIV/0! | BQ7: =SUM(BL7,BN7)/BD7*100 -> #DIV/0!
A8: BATAAN | B8: PROVINCIAL GOVERNMENT OF BATAAN | C8: BATAAN, PROVINCIAL GOVERNMENT OF BATAAN | D8: OUTSIDE MBA | F8: 14.676 | G8: 120.5295 | H8: =CONCATENATE(F8,",",G8) -> 14.676,120.5295 | I8: Provincial Plan | J8: NSWMC RESO NO. 1460 SERIES OF 2021 | K8: 2020 - 2030 | L8: 2021 | M8: 2030 | O8: 10.October | R8: Christle D. David | S8: R3-2025-035372 | T8: 45947 | U8: 45950 | W8: 45950 | X8: 45950 | Y8: =IF( OR(ISBLANK(T8), ISBLANK(U8)), "", MAX(1, IF( NETWORKDAYS(T8, U8) <= 0, 1, NETWORKDAYS(T8, U8) - IF(T8 = U8, 0, 1) )) ) -> 1 | Z8: =IF( OR(ISBLANK(U8), ISBLANK(V8)), "", MAX(1, IF( NETWORKDAYS(U8, V8) <= 0, 1, NETWORKDAYS(U8, V8) - IF(U8 = V8, 0, 1) )) ) | AA8: =IF( OR(IF(V8<>"", V8, U8)="", W8=""), "", MAX(1, IF( NETWORKDAYS(IF(V8<>"", V8, U8), W8) <= 0, 1, NETWORKDAYS(IF(V8<>"", V8, U8), W8) - IF(IF(V8<>"", V8, U8)=W8, 0, 1) ) ) ) -> 1 | AB8: =IF( OR(ISBLANK(W8), ISBLANK(X8)), "", MAX(1, IF( NETWORKDAYS(W8, X8) <= 0, 1, NETWORKDAYS(W8, X8) - IF(W8 = X8, 0, 1) )) ) -> 1 | AC8: Received by Planning | AD8: 0.394 | AE8: 367171.2 | AF8: 75.85 | AG8: Bataan Integrated Waste Management Facility | AH8: =IF(AND(AI8 = "YES", AJ8 = "YES", AK8 = "YES", AL8 = "YES", AN8 = "YES"), "Compliant", "Not Compliant") -> Compliant | AI8: YES | AJ8: YES | AK8: YES | AL8: YES | AN8: YES | BD8: =SUM(BF8,BH8,BJ8,BL8,BN8) -> 0 | BP8: =SUM(BF8,BH8,BJ8)/BD8*100 -> #DIV/0! | BQ8: =SUM(BL8,BN8)/BD8*100 -> #DIV/0!
A9: BULACAN | B9: SAN ILDEFONSO | C9: BULACAN, SAN ILDEFONSO | D9: MBA | E9: 3rd | F9: 15.077944 | G9: 120.94288 | H9: =CONCATENATE(F9,",",G9) -> 15.07794373,120.9428805 | I9: Municipal / City Plan | J9: 1245 | K9: 2017 - 2027 | L9: 2019 | M9: 2027 | O9: 10.October | P9: Ronaldo P. Roque, Jr. | Q9: Maria Cecilia Pascual | R9: Diozelle A. Lazatin | S9: R3-2025-034956 | T9: 45944 | U9: 45945 | V9: 45946 | W9: 45946 | X9: 45950 | Y9: 1 | Z9: =IF( OR(ISBLANK(U9), ISBLANK(V9)), "", MAX(1, IF( NETWORKDAYS(U9, V9) <= 0, 1, NETWORKDAYS(U9, V9) - IF(U9 = V9, 0, 1) )) ) -> 1 | AA9: =IF( OR(IF(V9<>"", V9, U9)="", W9=""), "", MAX(1, IF( NETWORKDAYS(IF(V9<>"", V9, U9), W9) <= 0, 1, NETWORKDAYS(IF(V9<>"", V9, U9), W9) - IF(IF(V9<>"", V9, U9)=W9, 0, 1) ) ) ) -> 1 | AB9: 2 | AC9: Received by Planning | AD9: 0.382 | AE9: 48,262.64kgs | AF9: 65 | AG9: ECO Protect | AH9: Compliant | AI9: YES | AJ9: YES | AK9: YES | AL9: YES | AM9: YES | AN9: YES | AR9: 54413.03 | AT9: 21025.2 | AV9: 14381.36 | AX9: 13369.28 | AZ9: 1708.57 | BB9: 3928.62 | BD9: =SUM(BF9,BH9,BJ9,BL9,BN9) -> 0 | BP9: =SUM(BF9,BH9,BJ9)/BD9*100 -> #DIV/0! | BQ9: =SUM(BL9,BN9)/BD9*100 -> #DIV/0!
A10: BULACAN | B10: SAN RAFAEL | C10: BULACAN, SAN RAFAEL | D10: MBA | E10: 3rd | F10: 14.982975 | G10: 120.92765 | H10: =CONCATENATE(F10,",",G10) -> 14.982975,120.927646 | I10: Municipal / City Plan | J10: NSWMC RESO NO. 168 SERIES OF 2015 | K10: 2015 - 2024 | L10: 2015 | M10: 2024 | N10: For Renewal | O10: 10.October | P10: Ronaldo P. Roque, Jr. | Q10: Maria Cecilia Pascual | R10: Diozelle A. Lazatin | S10: R3-2025-034066 | T10: 45938 | U10: 45939 | V10: 45945 | W10: 45945 | X10: 45950 | Y10: 1 | Z10: =IF( OR(ISBLANK(U10), ISBLANK(V10)), "", MAX(1, IF( NETWORKDAYS(U10, V10) <= 0, 1, NETWORKDAYS(U10, V10) - IF(U10 = V10, 0, 1) )) ) -> 4 | AA10: =IF( OR(IF(V10<>"", V10, U10)="", W10=""), "", MAX(1, IF( NETWORKDAYS(IF(V10<>"", V10, U10), W10) <= 0, 1, NETWORKDAYS(IF(V10<>"", V10, U10), W10) - IF(IF(V10<>"", V10, U10)=W10, 0, 1) ) ) ) -> 1 | AB10: =IF( OR(ISBLANK(W10), ISBLANK(X10)), "", MAX(1, IF( NETWORKDAYS(W10, X10) <= 0, 1, NETWORKDAYS(W10, X10) - IF(W10 = X10, 0, 1) )) ) -> 3 | AC10: Received by Planning | AH10: Compliant | AI10: YES | AJ10: YES | AK10: YES | AL10: YES | AM10: YES | AN10: YES | AR10: 61135.47 | AT10: 38857.71 | AV10: 11145 | AX10: 6969.44 | AZ10: 3631.45 | BB10: 531.88 | BD10: =SUM(BF10,BH10,BJ10,BL10,BN10) -> 0 | BP10: =SUM(BF10,BH10,BJ10)/BD10*100 -> #DIV/0! | BQ10: =SUM(BL10,BN10)/BD10*100 -> #DIV/0!
A11: NUEVA ECIJA | B11: CARRANGLAN | C11: NUEVA ECIJA, CARRANGLAN | D11: MBA | E11: 2nd | F11: 15.960408 | G11: 121.06312 | H11: =CONCATENATE(F11,",",G11) -> 15.960408,121.063117 | I11: Municipal / City Plan | J11: 1329 | K11: 2017 - 2027 | L11: 2019 | M11: 2027 | O11: 10.October | P11: Aser A. Inocencio, Jr. | Q11: Jaypee Ordoñez | R11: Zosimo P. Suyat | S11: R3-2025-035170 | T11: 45944 | U11: 45946 | V11: 45947 | W11: 45947 | X11: 45947 | Y11: =IF( OR(ISBLANK(T11), ISBLANK(U11)), "", MAX(1, IF( NETWORKDAYS(T11, U11) <= 0, 1, NETWORKDAYS(T11, U11) - IF(T11 = U11, 0, 1) )) ) -> 2 | Z11: =IF( OR(ISBLANK(U11), ISBLANK(V11)), "", MAX(1, IF( NETWORKDAYS(U11, V11) <= 0, 1, NETWORKDAYS(U11, V11) - IF(U11 = V11, 0, 1) )) ) -> 1 | AA11: =IF( OR(IF(V11<>"", V11, U11)="", W11=""), "", MAX(1, IF( NETWORKDAYS(IF(V11<>"", V11, U11), W11) <= 0, 1, NETWORKDAYS(IF(V11<>"", V11, U11), W11) - IF(IF(V11<>"", V11, U11)=W11, 0, 1) ) ) ) -> 1 | AB11: =IF( OR(ISBLANK(W11), ISBLANK(X11)), "", MAX(1, IF( NETWORKDAYS(W11, X11) <= 0, 1, NETWORKDAYS(W11, X11) - IF(W11 = X11, 0, 1) )) ) -> 1 | AC11: Received by Planning | AD11: 0.25 | AE11: 10605 | AF11: 88 | AG11: Primawaste | AH11: =IF(AND(AI11 = "YES", AJ11 = "YES", AK11 = "YES", AL11 = "YES", AN11 = "YES"), "Compliant", "Not Compliant") -> Not Compliant | AI11: YES | AJ11: YES | AK11: YES | AM11: YES | AN11: YES | AR11: 12429.33 | AT11: 7073.53 | AV11: 3222.93 | AX11: 646.33 | AZ11: 1378.41 | BB11: 108.14 | BD11: =SUM(BF11,BH11,BJ11,BL11,BN11) -> 0 | BP11: =SUM(BF11,BH11,BJ11)/BD11*100 -> #DIV/0! | BQ11: =SUM(BL11,BN11)/BD11*100 -> #DIV/0!
A12: NUEVA ECIJA | B12: SCIENCE CITY OF MUñOZ | C12: NUEVA ECIJA, SCIENCE CITY OF MUñOZ | D12: MBA | E12: 2nd | F12: 15.713327 | G12: 120.90397 | H12: =CONCATENATE(F12,",",G12) -> 15.713327,120.903968 | I12: Municipal / City Plan | J12: 1085 s. 2018 | K12: 2018 - 2027 | L12: 2018 | M12: 2027 | O12: 10.October | P12: Aser A. Inocencio, Jr. | Q12: Jaypee Ordoñez | R12: Zosimo P. Suyat | S12: R3-2025-035172 | T12: 45945 | U12: 45946 | V12: 45947 | W12: 45947 | X12: 45947 | Y12: =IF( OR(ISBLANK(T12), ISBLANK(U12)), "", MAX(1, IF( NETWORKDAYS(T12, U12) <= 0, 1, NETWORKDAYS(T12, U12) - IF(T12 = U12, 0, 1) )) ) -> 1 | Z12: =IF( OR(ISBLANK(U12), ISBLANK(V12)), "", MAX(1, IF( NETWORKDAYS(U12, V12) <= 0, 1, NETWORKDAYS(U12, V12) - IF(U12 = V12, 0, 1) )) ) -> 1 | AA12: =IF( OR(IF(V12<>"", V12, U12)="", W12=""), "", MAX(1, IF( NETWORKDAYS(IF(V12<>"", V12, U12), W12) <= 0, 1, NETWORKDAYS(IF(V12<>"", V12, U12), W12) - IF(IF(V12<>"", V12, U12)=W12, 0, 1) ) ) ) -> 1 | AB12: =IF( OR(ISBLANK(W12), ISBLANK(X12)), "", MAX(1, IF( NETWORKDAYS(W12, X12) <= 0, 1, NETWORKDAYS(W12, X12) - IF(W12 = X12, 0, 1) )) ) -> 1 | AC12: Received by Planning | AD12: 0.376 | AE12: 31699.81 | AF12: 89 | AG12: Metro Waste | AH12: =IF(AND(AI12 = "YES", AJ12 = "YES", AK12 = "YES", AL12 = "YES", AN12 = "YES"), "Compliant", "Not Compliant") -> Compliant | AI12: YES | AJ12: YES | AK12: YES | AL12: YES | AM12: YES | AN12: YES | AR12: 37520.29 | AT12: 22095.7 | AV12: 6794.92 | AX12: 4584.98 | AZ12: 3902.11 | BB12: 142.58 | BD12: =SUM(BF12,BH12,BJ12,BL12,BN12) -> 0 | BP12: =SUM(BF12,BH12,BJ12)/BD12*100 -> #DIV/0! | BQ12: =SUM(BL12,BN12)/BD12*100 -> #DIV/0!
A13: NUEVA ECIJA | B13: STO DOMINGO | C13: NUEVA ECIJA, STO DOMINGO | D13: MBA | E13: 1st | F13: 15.596054 | G13: 120.8774 | H13: =CONCATENATE(F13,",",G13) -> 15.596054,120.877399 | I13: Municipal / City Plan | J13: NSWMC RESO NO. 588-A SERIES OF 2020 | K13: 2017 - 2027 | L13: 2020 | M13: 2027 | O13: 10.October | P13: Gem C. Vicencio | Q13: Jaypee Ordoñez | R13: Zosimo P. Suyat | S13: R3-2025-035071 | T13: 45945 | U13: 45946 | V13: 45947 | W13: 45947 | X13: 45947 | Y13: =IF( OR(ISBLANK(T13), ISBLANK(U13)), "", MAX(1, IF( NETWORKDAYS(T13, U13) <= 0, 1, NETWORKDAYS(T13, U13) - IF(T13 = U13, 0, 1) )) ) -> 1 | Z13: =IF( OR(ISBLANK(U13), ISBLANK(V13)), "", MAX(1, IF( NETWORKDAYS(U13, V13) <= 0, 1, NETWORKDAYS(U13, V13) - IF(U13 = V13, 0, 1) )) ) -> 1 | AA13: =IF( OR(IF(V13<>"", V13, U13)="", W13=""), "", MAX(1, IF( NETWORKDAYS(IF(V13<>"", V13, U13), W13) <= 0, 1, NETWORKDAYS(IF(V13<>"", V13, U13), W13) - IF(IF(V13<>"", V13, U13)=W13, 0, 1) ) ) ) -> 1 | AB13: =IF( OR(ISBLANK(W13), ISBLANK(X13)), "", MAX(1, IF( NETWORKDAYS(W13, X13) <= 0, 1, NETWORKDAYS(W13, X13) - IF(W13 = X13, 0, 1) )) ) -> 1 | AC13: Received by Planning | AD13: 0.378 | AE13: 23092.78 | AF13: 81 | AG13: Metro Waste | AH13: =IF(AND(AI13 = "YES", AJ13 = "YES", AK13 = "YES", AL13 = "YES", AN13 = "YES"), "Compliant", "Not Compliant") -> Compliant | AI13: YES | AJ13: YES | AK13: YES | AL13: YES | AM13: YES | AN13: YES | AR13: 24761.15 | AT13: 13509.68 | AV13: 4033.59 | AX13: 2545.45 | AZ13: 4286.16 | BB13: 386.27 | BD13: =SUM(BF13,BH13,BJ13,BL13,BN13) -> 0 | BP13: =SUM(BF13,BH13,BJ13)/BD13*100 -> #DIV/0! | BQ13: =SUM(BL13,BN13)/BD13*100 -> #DIV/0!
A14: NUEVA ECIJA | B14: TALAVERA | C14: NUEVA ECIJA, TALAVERA | D14: MBA | E14: 1st | F14: 15.584241 | G14: 120.9184 | H14: =CONCATENATE(F14,",",G14) -> 15.584241,120.918404 | I14: Municipal / City Plan | J14: 1063 s. 2018 | K14: 2017 - 2026 | L14: 2018 | M14: 2026 | O14: 10.October | P14: Gem C. Vicencio | Q14: Jaypee Ordoñez | R14: Zosimo P. Suyat | S14: R3-2025-034954 | T14: 45944 | U14: 45946 | V14: 45947 | W14: 45947 | X14: 45947 | Y14: =IF( OR(ISBLANK(T14), ISBLANK(U14)), "", MAX(1, IF( NETWORKDAYS(T14, U14) <= 0, 1, NETWORKDAYS(T14, U14) - IF(T14 = U14, 0, 1) )) ) -> 2 | Z14: =IF( OR(ISBLANK(U14), ISBLANK(V14)), "", MAX(1, IF( NETWORKDAYS(U14, V14) <= 0, 1, NETWORKDAYS(U14, V14) - IF(U14 = V14, 0, 1) )) ) -> 1 | AA14: =IF( OR(IF(V14<>"", V14, U14)="", W14=""), "", MAX(1, IF( NETWORKDAYS(IF(V14<>"", V14, U14), W14) <= 0, 1, NETWORKDAYS(IF(V14<>"", V14, U14), W14) - IF(IF(V14<>"", V14, U14)=W14, 0, 1) ) ) ) -> 1 | AB14: =IF( OR(ISBLANK(W14), ISBLANK(X14)), "", MAX(1, IF( NETWORKDAYS(W14, X14) <= 0, 1, NETWORKDAYS(W14, X14) - IF(W14 = X14, 0, 1) )) ) -> 1 | AC14: Received by Planning | AD14: 0.277 | AE14: 36657.63 | AF14: 93 | AG14: Metro Waste | AH14: =IF(AND(AI14 = "YES", AJ14 = "YES", AK14 = "YES", AL14 = "YES", AN14 = "YES"), "Compliant", "Not Compliant") -> Compliant | AI14: YES | AJ14: YES | AK14: YES | AL14: YES | AM14: YES | AN14: YES | AR14: 41301.85 | AT14: 25520.41 | AV14: 9598.55 | AX14: 3312.41 | AZ14: 2643.32 | BB14: 227.16 | BD14: =SUM(BF14,BH14,BJ14,BL14,BN14) -> 0 | BP14: =SUM(BF14,BH14,BJ14)/BD14*100 -> #DIV/0! | BQ14: =SUM(BL14,BN14)/BD14*100 -> #DIV/0!
A15: PAMPANGA | B15: SAN SIMON | C15: PAMPANGA, SAN SIMON | D15: MBA | E15: 4th | F15: 14.9848 | G15: 120.7514 | H15: =CONCATENATE(F15,",",G15) -> 14.9848,120.7514 | I15: Municipal / City Plan | J15: 1333 series of 2019 | K15: 2017 - 2028 | L15: 2019 | M15: 2028 | O15: 10.October | P15: Glaiza S.Gaza | R15: Yves Yshmael M. Balagtas | S15: R3-2025-034978 | T15: 45944 | U15: 45945 | W15: 45946 | X15: 45950 | Y15: =IF( OR(ISBLANK(T15), ISBLANK(U15)), "", MAX(1, IF( NETWORKDAYS(T15, U15) <= 0, 1, NETWORKDAYS(T15, U15) - IF(T15 = U15, 0, 1) )) ) -> 1 | Z15: =IF( OR(ISBLANK(U15), ISBLANK(V15)), "", MAX(1, IF( NETWORKDAYS(U15, V15) <= 0, 1, NETWORKDAYS(U15, V15) - IF(U15 = V15, 0, 1) )) ) | AA15: =IF( OR(IF(V15<>"", V15, U15)="", W15=""), "", MAX(1, IF( NETWORKDAYS(IF(V15<>"", V15, U15), W15) <= 0, 1, NETWORKDAYS(IF(V15<>"", V15, U15), W15) - IF(IF(V15<>"", V15, U15)=W15, 0, 1) ) ) ) -> 1 | AB15: =IF( OR(ISBLANK(W15), ISBLANK(X15)), "", MAX(1, IF( NETWORKDAYS(W15, X15) <= 0, 1, NETWORKDAYS(W15, X15) - IF(W15 = X15, 0, 1) )) ) -> 2 | AC15: Received by Planning | AD15: 0.498 | AE15: 29472.63 | AF15: 45.65 | AG15: Floridablanca Enviro Corp. | AH15: =IF(AND(AI15 = "YES", AJ15 = "YES", AK15 = "YES", AL15 = "YES", AN15 = "YES"), "Compliant", "Not Compliant") -> Not Compliant | AI15: YES | AJ15: NO | AK15: YES | AL15: YES | AM15: YES | AN15: YES | AR15: 38991.91 | AT15: 12516.4 | AV15: 6020.35 | AX15: 10543.41 | AZ15: 2706.04 | BB15: 7205.7 | BD15: =SUM(BF15,BH15,BJ15,BL15,BN15) -> 0 | BP15: =SUM(BF15,BH15,BJ15)/BD15*100 -> #DIV/0! | BQ15: =SUM(BL15,BN15)/BD15*100 -> #DIV/0!
A16: TARLAC | B16: MAYANTOC | C16: TARLAC, MAYANTOC | D16: OUTSIDE MBA | E16: 1st | F16: 15.618876 | G16: 120.37812 | H16: =CONCATENATE(F16,",",G16) -> 15.6188757,120.3781159 | I16: Municipal / City Plan | J16: NSWMC Reso No. 1359 s 2019 | K16: 2017 - 2027 | L16: 2019 | M16: 2027 | O16: 10.October | P16: Jasper Kieht B. Pili | R16: Jan Emerson C. Gonzales | S16: R3-2025-035011 | T16: 45946 | U16: 45946 | W16: 45946 | X16: 45947 | Y16: =IF( OR(ISBLANK(T16), ISBLANK(U16)), "", MAX(1, IF( NETWORKDAYS(T16, U16) <= 0, 1, NETWORKDAYS(T16, U16) - IF(T16 = U16, 0, 1) )) ) -> 1 | Z16: =IF( OR(ISBLANK(U16), ISBLANK(V16)), "", MAX(1, IF( NETWORKDAYS(U16, V16) <= 0, 1, NETWORKDAYS(U16, V16) - IF(U16 = V16, 0, 1) )) ) | AA16: =IF( OR(ISBLANK(U16), ISBLANK(W16)), "", MAX(1, IF( NETWORKDAYS(U16, W16) <= 0, 1, NETWORKDAYS(U16, W16) - IF(U16 = W16, 0, 1) )) ) -> 1 | AB16: =IF( OR(ISBLANK(W16), ISBLANK(X16)), "", MAX(1, IF( NETWORKDAYS(W16, X16) <= 0, 1, NETWORKDAYS(W16, X16) - IF(W16 = X16, 0, 1) )) ) -> 1 | AC16: Received by Planning | AD16: 0.28 | AE16: 9933.56 | AF16: 3.27 | AG16: MAA Integraded Waste Solution Corporation | AH16: =IF(AND(AI16 = "YES", AJ16 = "YES", AK16 = "YES", AL16 = "YES", AN16 = "YES"), "Compliant", "Not Compliant") -> Not Compliant | AI16: YES | AJ16: YES | AK16: NO | AL16: NO | AM16: NO | AN16: YES | AR16: 9311.35 | AT16: 6343.83 | AV16: 1469.33 | AX16: 744.91 | AZ16: 593.13 | BB16: 160.16 | BD16: =SUM(BF16,BH16,BJ16,BL16,BN16) -> 0 | BP16: =SUM(BF16,BH16,BJ16)/BD16*100 -> #DIV/0! | BQ16: =SUM(BL16,BN16)/BD16*100 -> #DIV/0!
A17: ZAMBALES | B17: CANDELARIA | C17: ZAMBALES, CANDELARIA | D17: OUTSIDE MBA | E17: 2nd | F17: 15.626389 | G17: 119.93139 | H17: =CONCATENATE(F17,",",G17) -> 15.626389,119.931389 | I17: Municipal / City Plan | J17: NSWMC RESO NO. 1446 SERIES OF 2021 | K17: 2020 - 2029 | L17: 2021 | M17: 2029 | O17: 10.October | P17: Ryan Ace R. Angel | Q17: Ryan Christian R. Nunag | R17: Jun D. Guillermo | S17: R3-2025-033415 | T17: 45932 | U17: 45936 | V17: 45936 | W17: 45936 | X17: 45940 | Y17: =IF( OR(ISBLANK(T17), ISBLANK(U17)), "", MAX(1, IF( NETWORKDAYS(T17, U17) <= 0, 1, NETWORKDAYS(T17, U17) - IF(T17 = U17, 0, 1) )) ) -> 2 | Z17: =IF( OR(ISBLANK(U17), ISBLANK(V17)), "", MAX(1, IF( NETWORKDAYS(U17, V17) <= 0, 1, NETWORKDAYS(U17, V17) - IF(U17 = V17, 0, 1) )) ) -> 1 | AA17: =IF( OR(ISBLANK(U17), ISBLANK(W17)), "", MAX(1, IF( NETWORKDAYS(U17, W17) <= 0, 1, NETWORKDAYS(U17, W17) - IF(U17 = W17, 0, 1) )) ) -> 1 | AB17: =IF( OR(ISBLANK(W17), ISBLANK(X17)), "", MAX(1, IF( NETWORKDAYS(W17, X17) <= 0, 1, NETWORKDAYS(W17, X17) - IF(W17 = X17, 0, 1) )) ) -> 4 | AC17: Received by Planning | AH17: Compliant | AR17: 13091.82 | AT17: 3686.66 | AV17: 4443.37 | AX17: 864.06 | AZ17: 4019.19 | BB17: 78.55 | BD17: =SUM(BF17,BH17,BJ17,BL17,BN17) -> 0 | BP17: =SUM(BF17,BH17,BJ17)/BD17*100 -> #DIV/0! | BQ17: =SUM(BL17,BN17)/BD17*100 -> #DIV/0!
A18: AURORA | B18: DILASAG | C18: AURORA, DILASAG | D18: OUTSIDE MBA | E18: Lone | F18: 16.392731 | G18: 122.21173 | H18: =CONCATENATE(F18,",",G18) -> 16.392731,122.211731 | I18: Municipal / City Plan | J18: 504 A series of 2018 | K18: 2017 - 2027 | L18: 2018 | M18: 2027 | O18: 11.November | P18: Queenyvel Laguisma | R18: Ryan Christian R. Nunag | S18: R3-2025-037356 | T18: 45967 | U18: 45968 | W18: 45972 | X18: 45975 | Y18: =IF( OR(ISBLANK(T18), ISBLANK(U18)), "", MAX(1, IF( NETWORKDAYS(T18, U18) <= 0, 1, NETWORKDAYS(T18, U18) - IF(T18 = U18, 0, 1) )) ) -> 1 | Z18: =IF( OR(ISBLANK(U18), ISBLANK(V18)), "", MAX(1, IF( NETWORKDAYS(U18, V18) <= 0, 1, NETWORKDAYS(U18, V18) - IF(U18 = V18, 0, 1) )) ) | AA18: =IF( OR(IF(V18<>"", V18, U18)="", W18=""), "", MAX(1, IF( NETWORKDAYS(IF(V18<>"", V18, U18), W18) <= 0, 1, NETWORKDAYS(IF(V18<>"", V18, U18), W18) - IF(IF(V18<>"", V18, U18)=W18, 0, 1) ) ) ) -> 2 | AB18: =IF( OR(ISBLANK(W18), ISBLANK(X18)), "", MAX(1, IF( NETWORKDAYS(W18, X18) <= 0, 1, NETWORKDAYS(W18, X18) - IF(W18 = X18, 0, 1) )) ) -> 3 | AC18: Received by Planning | AD18: 0.3 | AE18: 5,260.80 kg/day | AF18: 0.9374 | AG18: Floridablanca Enviro Corporation | AH18: =IF(AND(AI18 = "YES", AJ18 = "YES", AK18 = "YES", AL18 = "YES", AN18 = "YES"), "Compliant", "Not Compliant") -> Compliant | AI18: YES | AJ18: YES | AK18: YES | AL18: YES | AM18: YES | AN18: YES | AR18: 6013.19 | AT18: 4195.41 | AV18: 1334.33 | AX18: 107.03 | AZ18: 234.51 | BB18: 141.91 | BD18: =SUM(BF18,BH18,BJ18,BL18,BN18) -> 0 | BP18: =SUM(BF18,BH18,BJ18)/BD18*100 -> #DIV/0! | BQ18: =SUM(BL18,BN18)/BD18*100 -> #DIV/0!
A19: AURORA | B19: DINGALAN | C19: AURORA, DINGALAN | D19: OUTSIDE MBA | E19: Lone | F19: 15.388964 | G19: 121.39117 | H19: =CONCATENATE(F19,",",G19) -> 15.388964,121.39117 | I19: Municipal / City Plan | J19: 1234 Series 2019 | K19: 2017 - 2027 | L19: 2019 | M19: 2027 | O19: 11.November | P19: Nikko Jay M. Valenzuela | R19: Ryan Christian R. Nunag | S19: R3-2025-037799 | T19: 45960 | U19: 45972 | W19: 45972 | X19: 45975 | Y19: =IF( OR(ISBLANK(T19), ISBLANK(U19)), "", MAX(1, IF( NETWORKDAYS(T19, U19) <= 0, 1, NETWORKDAYS(T19, U19) - IF(T19 = U19, 0, 1) )) ) -> 8 | Z19: =IF( OR(ISBLANK(U19), ISBLANK(V19)), "", MAX(1, IF( NETWORKDAYS(U19, V19) <= 0, 1, NETWORKDAYS(U19, V19) - IF(U19 = V19, 0, 1) )) ) | AA19: =IF( OR(IF(V19<>"", V19, U19)="", W19=""), "", MAX(1, IF( NETWORKDAYS(IF(V19<>"", V19, U19), W19) <= 0, 1, NETWORKDAYS(IF(V19<>"", V19, U19), W19) - IF(IF(V19<>"", V19, U19)=W19, 0, 1) ) ) ) -> 1 | AB19: =IF( OR(ISBLANK(W19), ISBLANK(X19)), "", MAX(1, IF( NETWORKDAYS(W19, X19) <= 0, 1, NETWORKDAYS(W19, X19) - IF(W19 = X19, 0, 1) )) ) -> 3 | AC19: Received by Planning | AD19: 0.36 | AE19: 12, 582.71 kg/day | AF19: 92.12 | AG19: LGU owned SLF | AH19: =IF(AND(AI19 = "YES", AJ19 = "YES", AK19 = "YES", AL19 = "YES", AN19 = "YES"), "Compliant", "Not Compliant") -> Compliant | AI19: YES | AJ19: YES | AK19: YES | AL19: YES | AM19: YES | AN19: YES | AR19: 15928.22 | AT19: 10257.77 | AV19: 2564.44 | AX19: 1850.86 | AZ19: 1035.33 | BB19: 219.81 | BD19: =SUM(BF19,BH19,BJ19,BL19,BN19) -> 0 | BP19: =SUM(BF19,BH19,BJ19)/BD19*100 -> #DIV/0! | BQ19: =SUM(BL19,BN19)/BD19*100 -> #DIV/0!
A20: BULACAN | B20: SAN MIGUEL | C20: BULACAN, SAN MIGUEL | D20: MBA | E20: 3rd | F20: 15.140474 | G20: 120.97742 | H20: =CONCATENATE(F20,",",G20) -> 15.140474,120.977422 | I20: Municipal / City Plan | J20: NSWMC RESO NO. 179A S 2015 | K20: 2015 - 2025 | L20: 2015 | M20: 2025 | N20: For Renewal | O20: 11.November | P20: Ronaldo P. Roque, Jr. | Q20: Maria Cecilia Pascual | R20: Diozelle A. Lazatin | S20: R3-2025-037390 | T20: 45965 | U20: 45969 | V20: 45979 | W20: 45980 | X20: 45980 | Y20: =IF( OR(ISBLANK(T20), ISBLANK(U20)), "", MAX(1, IF( NETWORKDAYS(T20, U20) <= 0, 1, NETWORKDAYS(T20, U20) - IF(T20 = U20, 0, 1) )) ) -> 3 | Z20: =IF( OR(ISBLANK(U20), ISBLANK(V20)), "", MAX(1, IF( NETWORKDAYS(U20, V20) <= 0, 1, NETWORKDAYS(U20, V20) - IF(U20 = V20, 0, 1) )) ) -> 6 | AA20: =IF( OR(IF(V20<>"", V20, U20)="", W20=""), "", MAX(1, IF( NETWORKDAYS(IF(V20<>"", V20, U20), W20) <= 0, 1, NETWORKDAYS(IF(V20<>"", V20, U20), W20) - IF(IF(V20<>"", V20, U20)=W20, 0, 1) ) ) ) -> 1 | AB20: =IF( OR(ISBLANK(W20), ISBLANK(X20)), "", MAX(1, IF( NETWORKDAYS(W20, X20) <= 0, 1, NETWORKDAYS(W20, X20) - IF(W20 = X20, 0, 1) )) ) -> 1 | AC20: Received by Planning | AD20: 0.3394 | AE20: 71811.45 | AF20: 95.16 | AH20: =IF(AND(AI20 = "YES", AJ20 = "YES", AK20 = "YES", AL20 = "YES", AN20 = "YES"), "Compliant", "Not Compliant") -> Not Compliant | AR20: 67480.78 | AT20: 44017.71 | AV20: 13232.98 | AX20: 6964.02 | AZ20: 3023.14 | BB20: 242.93 | BD20: =SUM(BF20,BH20,BJ20,BL20,BN20) -> 0 | BP20: =SUM(BF20,BH20,BJ20)/BD20*100 -> #DIV/0! | BQ20: =SUM(BL20,BN20)/BD20*100 -> #DIV/0!
A21: NUEVA ECIJA | B21: CABANATUAN | C21: NUEVA ECIJA, CABANATUAN | D21: MBA | E21: 3rd | F21: 15.470778 | G21: 120.9521 | H21: =CONCATENATE(F21,",",G21) -> 15.470778,120.952099 | I21: Municipal / City Plan | J21: NSWMC RESO NO. 1513 SERIES OF 2022 | K21: 2020 - 2029 | L21: 2022 | M21: 2029 | O21: 11.November | P21: Christian Jem L. Buluran | Q21: Jaypee Ordoñez | R21: Zosimo P. Suyat | S21: R3-2025-037837 | T21: 45968 | U21: 45972 | V21: 45980 | W21: 45980 | X21: 45980 | Y21: =IF( OR(ISBLANK(T21), ISBLANK(U21)), "", MAX(1, IF( NETWORKDAYS(T21, U21) <= 0, 1, NETWORKDAYS(T21, U21) - IF(T21 = U21, 0, 1) )) ) -> 2 | Z21: =IF( OR(ISBLANK(U21), ISBLANK(V21)), "", MAX(1, IF( NETWORKDAYS(U21, V21) <= 0, 1, NETWORKDAYS(U21, V21) - IF(U21 = V21, 0, 1) )) ) -> 6 | AA21: =IF( OR(IF(V21<>"", V21, U21)="", W21=""), "", MAX(1, IF( NETWORKDAYS(IF(V21<>"", V21, U21), W21) <= 0, 1, NETWORKDAYS(IF(V21<>"", V21, U21), W21) - IF(IF(V21<>"", V21, U21)=W21, 0, 1) ) ) ) -> 1 | AB21: =IF( OR(ISBLANK(W21), ISBLANK(X21)), "", MAX(1, IF( NETWORKDAYS(W21, X21) <= 0, 1, NETWORKDAYS(W21, X21) - IF(W21 = X21, 0, 1) )) ) -> 1 | AC21: Received by Planning | AD21: 0.363 | AG21: Prime Waste Solutions Inc. | AH21: =IF(AND(AI21 = "YES", AJ21 = "YES", AK21 = "YES", AL21 = "YES", AN21 = "YES"), "Compliant", "Not Compliant") -> Compliant | AI21: YES | AJ21: YES | AK21: YES | AL21: YES | AM21: YES | AN21: YES | AR21: 140635.62 | AT21: 74705.64 | AV21: 34104.14 | AX21: 10111.7 | AZ21: 21348.49 | BB21: 365.65 | BD21: =SUM(BF21,BH21,BJ21,BL21,BN21) -> 0 | BP21: =SUM(BF21,BH21,BJ21)/BD21*100 -> #DIV/0! | BQ21: =SUM(BL21,BN21)/BD21*100 -> #DIV/0!
A22: NUEVA ECIJA | B22: LUPAO | C22: NUEVA ECIJA, LUPAO | D22: MBA | E22: 2nd | F22: 15.877262 | G22: 120.8989 | H22: =CONCATENATE(F22,",",G22) -> 15.877262,120.898901 | I22: Municipal / City Plan | J22: 1065 Series of 2018 | K22: 2017 - 2026 | L22: 2018 | M22: 2026 | O22: 11.November | P22: Aser A. Inocencio, Jr. | Q22: Jaypee Ordoñez | R22: Zosimo P. Suyat | S22: R3-2025-037805 | T22: 45972 | U22: 45972 | V22: 45980 | W22: 45980 | X22: 45980 | Y22: =IF( OR(ISBLANK(T22), ISBLANK(U22)), "", MAX(1, IF( NETWORKDAYS(T22, U22) <= 0, 1, NETWORKDAYS(T22, U22) - IF(T22 = U22, 0, 1) )) ) -> 1 | Z22: =IF( OR(ISBLANK(U22), ISBLANK(V22)), "", MAX(1, IF( NETWORKDAYS(U22, V22) <= 0, 1, NETWORKDAYS(U22, V22) - IF(U22 = V22, 0, 1) )) ) -> 6 | AA22: =IF( OR(IF(V22<>"", V22, U22)="", W22=""), "", MAX(1, IF( NETWORKDAYS(IF(V22<>"", V22, U22), W22) <= 0, 1, NETWORKDAYS(IF(V22<>"", V22, U22), W22) - IF(IF(V22<>"", V22, U22)=W22, 0, 1) ) ) ) -> 1 | AB22: =IF( OR(ISBLANK(W22), ISBLANK(X22)), "", MAX(1, IF( NETWORKDAYS(W22, X22) <= 0, 1, NETWORKDAYS(W22, X22) - IF(W22 = X22, 0, 1) )) ) -> 1 | AC22: Received by Planning | AD22: 0.607 | AE22: 31609.92 | AF22: 92.47 | AG22: Metro Waste | AH22: =IF(AND(AI22 = "YES", AJ22 = "YES", AK22 = "YES", AL22 = "YES", AN22 = "YES"), "Compliant", "Not Compliant") -> Compliant | AI22: YES | AJ22: YES | AK22: YES | AL22: YES | AM22: YES | AN22: YES | AR22: 31609.92 | AT22: 19591.83 | AV22: 5680.3 | AX22: 3957.56 | AZ22: 1760.67 | BB22: 619.55 | BD22: =SUM(BF22,BH22,BJ22,BL22,BN22) -> 0 | BP22: =SUM(BF22,BH22,BJ22)/BD22*100 -> #DIV/0! | BQ22: =SUM(BL22,BN22)/BD22*100 -> #DIV/0!
A23: NUEVA ECIJA | B23: RIZAL | C23: NUEVA ECIJA, RIZAL | D23: MBA | E23: 2nd | F23: 15.707877 | G23: 121.10188 | H23: =CONCATENATE(F23,",",G23) -> 15.707877,121.101882 | I23: Municipal / City Plan | J23: 1288 SERIES 2019 | K23: 2017 - 2027 | L23: 2019 | M23: 2027 | O23: 11.November | P23: Hosannah R. Sabio | Q23: Jaypee Ordoñez | R23: Zosimo P. Suyat | S23: R3-2025-038732 | T23: 45972 | U23: 45980 | V23: 45980 | W23: 45980 | X23: 45980 | Y23: =IF( OR(ISBLANK(T23), ISBLANK(U23)), "", MAX(1, IF( NETWORKDAYS(T23, U23) <= 0, 1, NETWORKDAYS(T23, U23) - IF(T23 = U23, 0, 1) )) ) -> 6 | Z23: =IF( OR(ISBLANK(U23), ISBLANK(V23)), "", MAX(1, IF( NETWORKDAYS(U23, V23) <= 0, 1, NETWORKDAYS(U23, V23) - IF(U23 = V23, 0, 1) )) ) -> 1 | AA23: =IF( OR(IF(V23<>"", V23, U23)="", W23=""), "", MAX(1, IF( NETWORKDAYS(IF(V23<>"", V23, U23), W23) <= 0, 1, NETWORKDAYS(IF(V23<>"", V23, U23), W23) - IF(IF(V23<>"", V23, U23)=W23, 0, 1) ) ) ) -> 1 | AB23: =IF( OR(ISBLANK(W23), ISBLANK(X23)), "", MAX(1, IF( NETWORKDAYS(W23, X23) <= 0, 1, NETWORKDAYS(W23, X23) - IF(W23 = X23, 0, 1) )) ) -> 1 | AC23: Received by Planning | AD23: 0.461 | AH23: =IF(AND(AI23 = "YES", AJ23 = "YES", AK23 = "YES", AL23 = "YES", AN23 = "YES"), "Compliant", "Not Compliant") -> Not Compliant | AR23: 38680.41 | AT23: 23595.05 | AV23: 6567.93 | AX23: 3465.76 | AZ23: 4591.36 | BB23: 460.3 | BD23: =SUM(BF23,BH23,BJ23,BL23,BN23) -> 0 | BP23: =SUM(BF23,BH23,BJ23)/BD23*100 -> #DIV/0! | BQ23: =SUM(BL23,BN23)/BD23*100 -> #DIV/0!
A24: NUEVA ECIJA | B24: SAN ANTONIO | C24: NUEVA ECIJA, SAN ANTONIO | D24: MBA | E24: 4th | F24: 15.306809 | G24: 120.85671 | H24: =CONCATENATE(F24,",",G24) -> 15.306809,120.856712 | I24: Municipal / City Plan | J24: NSWMC RESO NO. 1490 SERIES OF 2021 | K24: 2020 - 2029 | L24: 2021 | M24: 2029 | O24: 11.November | P24: Christine Ann V. Ramos | Q24: Jaypee Ordoñez | R24: Zosimo P. Suyat | S24: R3-2025-036611 | T24: 45959 | U24: 45963 | V24: 45966 | W24: 45968 | X24: 45978 | Y24: =IF( OR(ISBLANK(T24), ISBLANK(U24)), "", MAX(1, IF( NETWORKDAYS(T24, U24) <= 0, 1, NETWORKDAYS(T24, U24) - IF(T24 = U24, 0, 1) )) ) -> 2 | Z24: =IF( OR(ISBLANK(U24), ISBLANK(V24)), "", MAX(1, IF( NETWORKDAYS(U24, V24) <= 0, 1, NETWORKDAYS(U24, V24) - IF(U24 = V24, 0, 1) )) ) -> 2 | AA24: =IF( OR(IF(V24<>"", V24, U24)="", W24=""), "", MAX(1, IF( NETWORKDAYS(IF(V24<>"", V24, U24), W24) <= 0, 1, NETWORKDAYS(IF(V24<>"", V24, U24), W24) - IF(IF(V24<>"", V24, U24)=W24, 0, 1) ) ) ) -> 2 | AB24: =IF( OR(ISBLANK(W24), ISBLANK(X24)), "", MAX(1, IF( NETWORKDAYS(W24, X24) <= 0, 1, NETWORKDAYS(W24, X24) - IF(W24 = X24, 0, 1) )) ) -> 6 | AC24: Received by Planning | AD24: 0.63 | AE24: 59542.48 | AF24: 84.18 | AG24: Urdaneta Waste Management | AH24: =IF(AND(AI24 = "YES", AJ24 = "YES", AK24 = "YES", AL24 = "YES", AN24 = "YES"), "Compliant", "Not Compliant") -> Compliant | AI24: YES | AJ24: YES | AK24: YES | AL24: YES | AM24: YES | AN24: YES | AR24: 59542.48 | AT24: 33689.14 | AV24: 13426.83 | AX24: 3006.9 | AZ24: 9276.72 | BB24: 142.9 | BD24: =SUM(BF24,BH24,BJ24,BL24,BN24) -> 0 | BP24: =SUM(BF24,BH24,BJ24)/BD24*100 -> #DIV/0! | BQ24: =SUM(BL24,BN24)/BD24*100 -> #DIV/0!
A25: NUEVA ECIJA | B25: TALUGTUG | C25: NUEVA ECIJA, TALUGTUG | D25: MBA | E25: 2nd | F25: 15.777162 | G25: 120.80776 | H25: =CONCATENATE(F25,",",G25) -> 15.777162,120.807756 | I25: Municipal / City Plan | J25: NSWMC RESO NO. 1078 SERIES OF 2018 | K25: 2017 - 2027 | L25: 2018 | M25: 2027 | O25: 11.November | P25: Aser A. Inocencio, Jr. | Q25: Jaypee Ordoñez | R25: Zosimo P. Suyat | S25: R3-2025-036959 | T25: 45959 | U25: 45965 | V25: 45972 | W25: 45972 | X25: 45978 | Y25: =IF( OR(ISBLANK(T25), ISBLANK(U25)), "", MAX(1, IF( NETWORKDAYS(T25, U25) <= 0, 1, NETWORKDAYS(T25, U25) - IF(T25 = U25, 0, 1) )) ) -> 4 | Z25: =IF( OR(ISBLANK(U25), ISBLANK(V25)), "", MAX(1, IF( NETWORKDAYS(U25, V25) <= 0, 1, NETWORKDAYS(U25, V25) - IF(U25 = V25, 0, 1) )) ) -> 5 | AA25: =IF( OR(IF(V25<>"", V25, U25)="", W25=""), "", MAX(1, IF( NETWORKDAYS(IF(V25<>"", V25, U25), W25) <= 0, 1, NETWORKDAYS(IF(V25<>"", V25, U25), W25) - IF(IF(V25<>"", V25, U25)=W25, 0, 1) ) ) ) -> 1 | AB25: =IF( OR(ISBLANK(W25), ISBLANK(X25)), "", MAX(1, IF( NETWORKDAYS(W25, X25) <= 0, 1, NETWORKDAYS(W25, X25) - IF(W25 = X25, 0, 1) )) ) -> 4 | AC25: Received by Planning | AD25: 0.205 | AE25: 5828.8 | AG25: Metro Waste Solid Waste Management Corporation | AH25: =IF(AND(AI25 = "YES", AJ25 = "YES", AK25 = "YES", AL25 = "YES", AN25 = "YES"), "Compliant", "Not Compliant") -> Not Compliant | AI25: NO | AJ25: YES | AK25: NO | AL25: NO | AM25: NO | AN25: YES | AO25: NO | AR25: 5828.8 | AT25: 3262.38 | AV25: 908.71 | AX25: 259.38 | AZ25: 1362.77 | BB25: 35.56 | BD25: =SUM(BF25,BH25,BJ25,BL25,BN25) -> 0 | BP25: =SUM(BF25,BH25,BJ25)/BD25*100 -> #DIV/0! | BQ25: =SUM(BL25,BN25)/BD25*100 -> #DIV/0!
A26: PAMPANGA | B26: ANGELES | C26: PAMPANGA, ANGELES | D26: MBA | E26: 1st | F26: 15.1653 | G26: 120.6084 | H26: =CONCATENATE(F26,",",G26) -> 15.1653,120.6084 | I26: Municipal / City Plan | J26: NSWMC RESO NO. 196 SERIES OF 2015 | K26: 2015 - 2024 | L26: 2015 | M26: 2024 | N26: For Renewal | O26: 11.November | P26: Elyza A. Evilla | R26: Yves Yshmael M. Balagtas | S26: R3-2025-037819 | T26: 45972 | U26: 45972 | W26: 45978 | X26: 45979 | Y26: =IF( OR(ISBLANK(T26), ISBLANK(U26)), "", MAX(1, IF( NETWORKDAYS(T26, U26) <= 0, 1, NETWORKDAYS(T26, U26) - IF(T26 = U26, 0, 1) )) ) -> 1 | Z26: =IF( OR(ISBLANK(U26), ISBLANK(V26)), "", MAX(1, IF( NETWORKDAYS(U26, V26) <= 0, 1, NETWORKDAYS(U26, V26) - IF(U26 = V26, 0, 1) )) ) | AA26: =IF( OR(IF(V26<>"", V26, U26)="", W26=""), "", MAX(1, IF( NETWORKDAYS(IF(V26<>"", V26, U26), W26) <= 0, 1, NETWORKDAYS(IF(V26<>"", V26, U26), W26) - IF(IF(V26<>"", V26, U26)=W26, 0, 1) ) ) ) -> 4 | AB26: =IF( OR(ISBLANK(W26), ISBLANK(X26)), "", MAX(1, IF( NETWORKDAYS(W26, X26) <= 0, 1, NETWORKDAYS(W26, X26) - IF(W26 = X26, 0, 1) )) ) -> 1 | AC26: Received by Planning | AD26: 0.5 | AE26: 79314 | AF26: 0.6 | AG26: Eco Protect Management Corp. | AH26: =IF(AND(AI26 = "YES", AJ26 = "YES", AK26 = "YES", AL26 = "YES", AN26 = "YES"), "Compliant", "Not Compliant") -> Not Compliant | AI26: YES | AJ26: YES | AK26: YES | AL26: NO | AM26: YES | AN26: YES | AR26: 293415.48 | AT26: 153925.76 | AV26: 56071.7 | AX26: 37967.96 | AZ26: 43865.61 | BB26: 1584.44 | BD26: =SUM(BF26,BH26,BJ26,BL26,BN26) -> 0 | BP26: =SUM(BF26,BH26,BJ26)/BD26*100 -> #DIV/0! | BQ26: =SUM(BL26,BN26)/BD26*100 -> #DIV/0!
A27: PAMPANGA | B27: ARAYAT | C27: PAMPANGA, ARAYAT | D27: MBA | E27: 3rd | F27: 15.154167 | G27: 120.7716 | H27: =CONCATENATE(F27,",",G27) -> 15.154167,120.771598 | I27: Municipal / City Plan | J27: 1038-A Series of 2019 | K27: 2017 -2028 | L27: 2019 | M27: 2028 | O27: 11.November | P27: Roger T. Encarnacion II | R27: Yves Yshmael M. Balagtas | S27: R3-2025-037414 | T27: 45967 | U27: 45970 | W27: 45978 | X27: 45979 | Y27: =IF( OR(ISBLANK(T27), ISBLANK(U27)), "", MAX(1, IF( NETWORKDAYS(T27, U27) <= 0, 1, NETWORKDAYS(T27, U27) - IF(T27 = U27, 0, 1) )) ) -> 1 | Z27: =IF( OR(ISBLANK(U27), ISBLANK(V27)), "", MAX(1, IF( NETWORKDAYS(U27, V27) <= 0, 1, NETWORKDAYS(U27, V27) - IF(U27 = V27, 0, 1) )) ) | AA27: =IF( OR(IF(V27<>"", V27, U27)="", W27=""), "", MAX(1, IF( NETWORKDAYS(IF(V27<>"", V27, U27), W27) <= 0, 1, NETWORKDAYS(IF(V27<>"", V27, U27), W27) - IF(IF(V27<>"", V27, U27)=W27, 0, 1) ) ) ) -> 5 | AB27: =IF( OR(ISBLANK(W27), ISBLANK(X27)), "", MAX(1, IF( NETWORKDAYS(W27, X27) <= 0, 1, NETWORKDAYS(W27, X27) - IF(W27 = X27, 0, 1) )) ) -> 1 | AC27: Received by Planning | AD27: 0.151 | AE27: 22221.68 | AF27: 94.44! | AG27: Floridablanca Enviro Corporation | AH27: =IF(AND(AI27 = "YES", AJ27 = "YES", AK27 = "YES", AL27 = "YES", AN27 = "YES"), "Compliant", "Not Compliant") -> Not Compliant | AI27: YES | AJ27: YES | AK27: YES | AL27: NO | AM27: YES | AN27: YES | AR27: 7030.51 | AT27: 3489.95 | AV27: 2057.83 | AX27: 338.17 | AZ27: 1096.76 | BB27: 47.81 | BD27: =SUM(BF27,BH27,BJ27,BL27,BN27) -> 0 | BP27: =SUM(BF27,BH27,BJ27)/BD27*100 -> #DIV/0! | BQ27: =SUM(BL27,BN27)/BD27*100 -> #DIV/0!
A28: TARLAC | B28: BAMBAN | C28: TARLAC, BAMBAN | D28: MBA | E28: 3rd | F28: 15.289574 | G28: 120.57066 | H28: =CONCATENATE(F28,",",G28) -> 15.289574,120.570662 | I28: Municipal / City Plan | J28: 1248 | K28: 2016 - 2027 | L28: 2019 | M28: 2027 | O28: 11.November | P28: Gretzhen M. Apolonio | Q28: Sherwin John Loquellano | R28: Jan Emerson C. Gonzales | S28: R3-2025-036979 | T28: 45965 | U28: 45968 | V28: 45978 | W28: 45978 | X28: 45978 | Y28: =IF( OR(ISBLANK(T28), ISBLANK(U28)), "", MAX(1, IF( NETWORKDAYS(T28, U28) <= 0, 1, NETWORKDAYS(T28, U28) - IF(T28 = U28, 0, 1) )) ) -> 3 | Z28: =IF( OR(ISBLANK(U28), ISBLANK(V28)), "", MAX(1, IF( NETWORKDAYS(U28, V28) <= 0, 1, NETWORKDAYS(U28, V28) - IF(U28 = V28, 0, 1) )) ) -> 6 | AA28: =IF( OR(IF(V28<>"", V28, U28)="", W28=""), "", MAX(1, IF( NETWORKDAYS(IF(V28<>"", V28, U28), W28) <= 0, 1, NETWORKDAYS(IF(V28<>"", V28, U28), W28) - IF(IF(V28<>"", V28, U28)=W28, 0, 1) ) ) ) -> 1 | AB28: =IF( OR(ISBLANK(W28), ISBLANK(X28)), "", MAX(1, IF( NETWORKDAYS(W28, X28) <= 0, 1, NETWORKDAYS(W28, X28) - IF(W28 = X28, 0, 1) )) ) -> 1 | AC28: Received by Planning | AD28: 0.368 | AE28: 26685.52 | AF28: 0.6852 | AG28: M.A.A Waste Integrated Solution Corporation | AH28: =IF(AND(AI28 = "YES", AJ28 = "YES", AK28 = "YES", AL28 = "YES", AN28 = "YES"), "Compliant", "Not Compliant") -> Compliant | AI28: YES | AJ28: YES | AK28: YES | AL28: YES | AM28: NO | AN28: YES | AR28: 36507.93 | AT28: 13697.78 | AV28: 11321.11 | AX28: 7243.17 | AZ28: 3720.16 | BB28: 525.71 | BD28: =SUM(BF28,BH28,BJ28,BL28,BN28) -> 0 | BP28: =SUM(BF28,BH28,BJ28)/BD28*100 -> #DIV/0! | BQ28: =SUM(BL28,BN28)/BD28*100 -> #DIV/0!
A29: TARLAC | B29: STA IGNACIA | C29: TARLAC, STA IGNACIA | D29: OUTSIDE MBA | E29: 1st | F29: 15.616387 | G29: 120.43469 | H29: =CONCATENATE(F29,",",G29) -> 15.616387,120.434693 | I29: Municipal / City Plan | J29: 1334 series of 2019 | K29: 2018 - 2027 | L29: 2019 | M29: 2027 | O29: 11.November | P29: Joshua A. Capones | Q29: Sherwin John Loquellano | R29: Jan Emerson C. Gonzales | S29: R3-2025-036967 | T29: 45965 | U29: 45965 | V29: 45967 | W29: 45967 | X29: 45978 | Y29: =IF( OR(ISBLANK(T29), ISBLANK(U29)), "", MAX(1, IF( NETWORKDAYS(T29, U29) <= 0, 1, NETWORKDAYS(T29, U29) - IF(T29 = U29, 0, 1) )) ) -> 1 | Z29: =IF( OR(ISBLANK(U29), ISBLANK(V29)), "", MAX(1, IF( NETWORKDAYS(U29, V29) <= 0, 1, NETWORKDAYS(U29, V29) - IF(U29 = V29, 0, 1) )) ) -> 2 | AA29: =IF( OR(ISBLANK(U29), ISBLANK(W29)), "", MAX(1, IF( NETWORKDAYS(U29, W29) <= 0, 1, NETWORKDAYS(U29, W29) - IF(U29 = W29, 0, 1) )) ) -> 2 | AB29: =IF( OR(ISBLANK(W29), ISBLANK(X29)), "", MAX(1, IF( NETWORKDAYS(W29, X29) <= 0, 1, NETWORKDAYS(W29, X29) - IF(W29 = X29, 0, 1) )) ) -> 7 | AC29: Received by Planning | AD29: 0.18 | AE29: 4576.11 | AG29: INTERNATIONAL SOLID WASTE INTEGRATED MNGT. SPECIALIST INC. (ISWIMS) | AH29: =IF(AND(AI29 = "YES", AJ29 = "YES", AK29 = "YES", AL29 = "YES", AN29 = "YES"), "Compliant", "Not Compliant") -> Compliant | AI29: YES | AJ29: YES | AK29: YES | AL29: YES | AM29: YES | AN29: YES | AO29: NO | AR29: 10998.93 | AT29: 4069.6 | AV29: 3629.65 | AX29: 1429.86 | AZ29: 1099.89 | BB29: 769.93 | BD29: =SUM(BF29,BH29,BJ29,BL29,BN29) -> 0 | BP29: =SUM(BF29,BH29,BJ29)/BD29*100 -> #DIV/0! | BQ29: =SUM(BL29,BN29)/BD29*100 -> #DIV/0!
A30: AURORA | B30: MARIA AURORA | C30: AURORA, MARIA AURORA | D30: OUTSIDE MBA | E30: Lone | F30: 15.798717 | G30: 121.47355 | H30: =CONCATENATE(F30,",",G30) -> 15.798717,121.47355 | I30: Municipal / City Plan | J30: NSWMC Resolution No. 139, Series of 2015 | K30: 2015 - 2024 | L30: 2025 | M30: 2034 | N30: Approved | O30: 2.February | P30: Nikko Jay M. Valenzuela | R30: Ryan Christian R. Nunag | S30: R3-2025-004099 | T30: 45692 | U30: 45694 | W30: 45695 | X30: 45695 | Y30: =IF( OR(ISBLANK(T30), ISBLANK(U30)), "", MAX(1, IF( NETWORKDAYS(T30, U30) <= 0, 1, NETWORKDAYS(T30, U30) - IF(T30 = U30, 0, 1) )) ) -> 2 | Z30: =IF( OR(ISBLANK(U30), ISBLANK(V30)), "", MAX(1, IF( NETWORKDAYS(U30, V30) <= 0, 1, NETWORKDAYS(U30, V30) - IF(U30 = V30, 0, 1) )) ) | AA30: =IF( OR(IF(V30<>"", V30, U30)="", W30=""), "", MAX(1, IF( NETWORKDAYS(IF(V30<>"", V30, U30), W30) <= 0, 1, NETWORKDAYS(IF(V30<>"", V30, U30), W30) - IF(IF(V30<>"", V30, U30)=W30, 0, 1) ) ) ) -> 1 | AB30: =IF( OR(ISBLANK(W30), ISBLANK(X30)), "", MAX(1, IF( NETWORKDAYS(W30, X30) <= 0, 1, NETWORKDAYS(W30, X30) - IF(W30 = X30, 0, 1) )) ) -> 1 | AC30: Received by Planning | AD30: 0.24 | AE30: 1825.36 | AF30: 5.24 | AG30: LGU owned SLF | AH30: Compliant | AI30: YES | AJ30: YES | AK30: YES | AL30: YES | AM30: N/A | AN30: YES | AQ30: On going review of the sumitted PLan | AR30: 12056.78 | AT30: 6789.17 | AV30: 1844.69 | AX30: 2629.58 | AZ30: 778.87 | BB30: 14.47 | BD30: =SUM(BF30,BH30,BJ30,BL30,BN30) -> 0 | BP30: =SUM(BF30,BH30,BJ30)/BD30*100 -> #DIV/0! | BQ30: =SUM(BL30,BN30)/BD30*100 -> #DIV/0!
A31: BATAAN | B31: DINALUPIHAN | C31: BATAAN, DINALUPIHAN | D31: MBA | E31: 3rd | F31: 14.866933 | G31: 120.4611 | H31: =CONCATENATE(F31,",",G31) -> 14.866933,120.461103 | I31: Municipal / City Plan | J31: 149 Series of 2015 | K31: 2015 - 2025 | L31: 2015 | M31: 2025 | N31: For Renewal | O31: 2.February | P31: John-lester Signio | R31: Christle D. David | S31: R3-2025-005077 | T31: 45699 | U31: 45700 | W31: 45701 | X31: 45701 | Y31: =IF( OR(ISBLANK(T31), ISBLANK(U31)), "", MAX(1, IF( NETWORKDAYS(T31, U31) <= 0, 1, NETWORKDAYS(T31, U31) - IF(T31 = U31, 0, 1) )) ) -> 1 | Z31: =IF( OR(ISBLANK(U31), ISBLANK(V31)), "", MAX(1, IF( NETWORKDAYS(U31, V31) <= 0, 1, NETWORKDAYS(U31, V31) - IF(U31 = V31, 0, 1) )) ) | AA31: =IF( OR(IF(V31<>"", V31, U31)="", W31=""), "", MAX(1, IF( NETWORKDAYS(IF(V31<>"", V31, U31), W31) <= 0, 1, NETWORKDAYS(IF(V31<>"", V31, U31), W31) - IF(IF(V31<>"", V31, U31)=W31, 0, 1) ) ) ) -> 1 | AB31: =IF( OR(ISBLANK(W31), ISBLANK(X31)), "", MAX(1, IF( NETWORKDAYS(W31, X31) <= 0, 1, NETWORKDAYS(W31, X31) - IF(W31 = X31, 0, 1) )) ) -> 1 | AC31: Received by Planning | AD31: 0.321 | AE31: 38095.24 | AF31: 90 | AG31: Floridablanca Enviro Corporation | AH31: Compliant | AI31: YES | AJ31: YES | AK31: YES | AL31: YES | AM31: YES | AN31: YES | AR31: 29103.01 | AT31: 12805.33 | AV31: 11641.21 | AX31: 1746.18 | AZ31: 1746.18 | BB31: 1164.12 | BD31: =SUM(BF31,BH31,BJ31,BL31,BN31) -> 0 | BP31: =SUM(BF31,BH31,BJ31)/BD31*100 -> #DIV/0! | BQ31: =SUM(BL31,BN31)/BD31*100 -> #DIV/0!
A32: BATAAN | B32: HERMOSA | C32: BATAAN, HERMOSA | D32: MBA | E32: 1st | F32: 14.830649 | G32: 120.50857 | H32: =CONCATENATE(F32,",",G32) -> 14.830649,120.508569 | I32: Municipal / City Plan | J32: NSWMC Resolution No. 1173 | K32: 2017 - 2027 | L32: 2018 | M32: 2027 | O32: 2.February | P32: John-lester Signio | R32: Christle D. David | S32: R3-2025-005565 | T32: 45701 | U32: 45704 | W32: 45705 | X32: 45705 | Y32: =IF( OR(ISBLANK(T32), ISBLANK(U32)), "", MAX(1, IF( NETWORKDAYS(T32, U32) <= 0, 1, NETWORKDAYS(T32, U32) - IF(T32 = U32, 0, 1) )) ) -> 1 | Z32: =IF( OR(ISBLANK(U32), ISBLANK(V32)), "", MAX(1, IF( NETWORKDAYS(U32, V32) <= 0, 1, NETWORKDAYS(U32, V32) - IF(U32 = V32, 0, 1) )) ) | AA32: =IF( OR(IF(V32<>"", V32, U32)="", W32=""), "", MAX(1, IF( NETWORKDAYS(IF(V32<>"", V32, U32), W32) <= 0, 1, NETWORKDAYS(IF(V32<>"", V32, U32), W32) - IF(IF(V32<>"", V32, U32)=W32, 0, 1) ) ) ) -> 1 | AB32: =IF( OR(ISBLANK(W32), ISBLANK(X32)), "", MAX(1, IF( NETWORKDAYS(W32, X32) <= 0, 1, NETWORKDAYS(W32, X32) - IF(W32 = X32, 0, 1) )) ) -> 1 | AC32: Received by Planning | AD32: 0.47 | AE32: 34698.22 | AF32: 85.4 | AG32: Hauler = 5-1 Construction Corporation | AH32: Compliant | AI32: YES | AJ32: YES | AK32: YES | AL32: YES | AM32: YES | AN32: YES | AR32: 50359.71 | AT32: 24555.4 | AV32: 14171.22 | AX32: 4280.58 | AZ32: 6712.95 | BB32: 639.57 | BD32: =SUM(BF32,BH32,BJ32,BL32,BN32) -> 0 | BP32: =SUM(BF32,BH32,BJ32)/BD32*100 -> #DIV/0! | BQ32: =SUM(BL32,BN32)/BD32*100 -> #DIV/0!
A33: BULACAN | B33: CALUMPIT | C33: BULACAN, CALUMPIT | D33: MBA | E33: 1st | F33: 14.91396 | G33: 120.76478 | H33: =CONCATENATE(F33,",",G33) -> 14.91396,120.764777 | I33: Municipal / City Plan | J33: 1082 series of 2018 | K33: 2017 - 2028 | L33: 2018 | M33: 2028 | O33: 2.February | P33: Ronaldo P. Roque, Jr. | Q33: Rod Ross S. De Jesus | R33: Diozelle A. Lazatin | S33: R3-2025-005555 | T33: 45702 | U33: 45704 | V33: 45705 | W33: 45705 | X33: 45706 | Y33: =IF( OR(ISBLANK(T33), ISBLANK(U33)), "", MAX(1, IF( NETWORKDAYS(T33, U33) <= 0, 1, NETWORKDAYS(T33, U33) - IF(T33 = U33, 0, 1) )) ) -> 1 | Z33: =IF( OR(ISBLANK(U33), ISBLANK(V33)), "", MAX(1, IF( NETWORKDAYS(U33, V33) <= 0, 1, NETWORKDAYS(U33, V33) - IF(U33 = V33, 0, 1) )) ) -> 1 | AA33: =IF( OR(IF(V33<>"", V33, U33)="", W33=""), "", MAX(1, IF( NETWORKDAYS(IF(V33<>"", V33, U33), W33) <= 0, 1, NETWORKDAYS(IF(V33<>"", V33, U33), W33) - IF(IF(V33<>"", V33, U33)=W33, 0, 1) ) ) ) -> 1 | AB33: =IF( OR(ISBLANK(W33), ISBLANK(X33)), "", MAX(1, IF( NETWORKDAYS(W33, X33) <= 0, 1, NETWORKDAYS(W33, X33) - IF(W33 = X33, 0, 1) )) ) -> 1 | AC33: Received by Planning | AD33: 0.368 | AE33: 43597.328 | AG33: Eco Protect Management Corporation | AH33: Compliant | AI33: YES | AJ33: NO | AK33: YES | AL33: YES | AN33: YES | AR33: 51602.34 | AT33: 23566.79 | AV33: 12694.18 | AX33: 11280.27 | AZ33: 2827.81 | BB33: 1233.3 | BD33: =SUM(BF33,BH33,BJ33,BL33,BN33) -> 0 | BP33: =SUM(BF33,BH33,BJ33)/BD33*100 -> #DIV/0! | BQ33: =SUM(BL33,BN33)/BD33*100 -> #DIV/0!
A34: BULACAN | B34: MALOLOS | C34: BULACAN, MALOLOS | D34: MBA | E34: 1st | F34: 14.843702 | G34: 120.81114 | H34: =CONCATENATE(F34,",",G34) -> 14.843702,120.811145 | I34: Municipal / City Plan | J34: NSWMC RESO NO. 503-A SERIES OF 2019 | K34: 2018-2028 | L34: 2019 | M34: 2028 | O34: 2.February | P34: Ronaldo P. Roque, Jr. | Q34: Rod Ross S. De Jesus | R34: Diozelle A. Lazatin | S34: R3-2025-004155 | T34: 45692 | U34: 45694 | V34: 45694 | W34: 45698 | X34: 45701 | Y34: =IF( OR(ISBLANK(T34), ISBLANK(U34)), "", MAX(1, IF( NETWORKDAYS(T34, U34) <= 0, 1, NETWORKDAYS(T34, U34) - IF(T34 = U34, 0, 1) )) ) -> 2 | Z34: =IF( OR(ISBLANK(U34), ISBLANK(V34)), "", MAX(1, IF( NETWORKDAYS(U34, V34) <= 0, 1, NETWORKDAYS(U34, V34) - IF(U34 = V34, 0, 1) )) ) -> 1 | AA34: =IF( OR(IF(V34<>"", V34, U34)="", W34=""), "", MAX(1, IF( NETWORKDAYS(IF(V34<>"", V34, U34), W34) <= 0, 1, NETWORKDAYS(IF(V34<>"", V34, U34), W34) - IF(IF(V34<>"", V34, U34)=W34, 0, 1) ) ) ) -> 2 | AB34: =IF( OR(ISBLANK(W34), ISBLANK(X34)), "", MAX(1, IF( NETWORKDAYS(W34, X34) <= 0, 1, NETWORKDAYS(W34, X34) - IF(W34 = X34, 0, 1) )) ) -> 3 | AC34: Received by Planning | AD34: 0.238 | AE34: 69116.39 | AF34: 100 | AG34: Eco Protect Management Corporation | AH34: Compliant | AI34: YES | AJ34: YES | AK34: YES | AL34: YES | AM34: YES | AN34: YES | AR34: 66654.05 | AT34: 37939.49 | AV34: 14490.59 | AX34: 8685.02 | AZ34: 3412.69 | BB34: 2126.26 | BD34: =SUM(BF34,BH34,BJ34,BL34,BN34) -> 0 | BP34: =SUM(BF34,BH34,BJ34)/BD34*100 -> #DIV/0! | BQ34: =SUM(BL34,BN34)/BD34*100 -> #DIV/0!
A35: NUEVA ECIJA | B35: CABIAO | C35: NUEVA ECIJA, CABIAO | D35: MBA | E35: 4th | F35: 15.252382 | G35: 120.86015 | H35: =CONCATENATE(F35,",",G35) -> 15.252382,120.860145 | I35: Municipal / City Plan | J35: 1365 series of 2019 | K35: 2017 - 2027 | L35: 2019 | M35: 2027 | O35: 2.February | P35: Christine Ann V. Ramos | Q35: Jaypee Ordoñez | R35: Zosimo P. Suyat | S35: R3-2025-003758 | T35: 45692 | U35: 45693 | V35: 45694 | W35: 45698 | X35: 45705 | Y35: =IF( OR(ISBLANK(T35), ISBLANK(U35)), "", MAX(1, IF( NETWORKDAYS(T35, U35) <= 0, 1, NETWORKDAYS(T35, U35) - IF(T35 = U35, 0, 1) )) ) -> 1 | Z35: =IF( OR(ISBLANK(U35), ISBLANK(V35)), "", MAX(1, IF( NETWORKDAYS(U35, V35) <= 0, 1, NETWORKDAYS(U35, V35) - IF(U35 = V35, 0, 1) )) ) -> 1 | AA35: =IF( OR(IF(V35<>"", V35, U35)="", W35=""), "", MAX(1, IF( NETWORKDAYS(IF(V35<>"", V35, U35), W35) <= 0, 1, NETWORKDAYS(IF(V35<>"", V35, U35), W35) - IF(IF(V35<>"", V35, U35)=W35, 0, 1) ) ) ) -> 2 | AB35: =IF( OR(ISBLANK(W35), ISBLANK(X35)), "", MAX(1, IF( NETWORKDAYS(W35, X35) <= 0, 1, NETWORKDAYS(W35, X35) - IF(W35 = X35, 0, 1) )) ) -> 5 | AC35: Received by Planning | AD35: 0.723 | AE35: 45349.47 | AH35: Compliant | AI35: YES | AJ35: YES | AK35: YES | AL35: YES | AM35: YES | AN35: YES | AR35: 65905.11 | AT35: 34000.45 | AV35: 8119.51 | AX35: 10564.59 | AZ35: 12805.36 | BB35: 415.2 | BD35: =SUM(BF35,BH35,BJ35,BL35,BN35) -> 0 | BP35: =SUM(BF35,BH35,BJ35)/BD35*100 -> #DIV/0! | BQ35: =SUM(BL35,BN35)/BD35*100 -> #DIV/0!
